Workbook

Sheet Individual data from NASA
A1: Source | B1: Campaign | C1: Fuel | D1: Engine | E1: nPoints | F1: Aromatics | G1: Naph | H1: Sulfur | I1: Hydrogen | J1: TempC | K1: Thrust | L1: FF | M1: nvPM EIn | N1: VolEIn | O1: ColdEIn | P1: mBC | Q1: Org_Fract | R1: SO4_Fract | S1: mOrg | T1: mSO4 | U1: ColdGMD | V1: ColdVMD | W1: HotGMD | X1: HotVMD
A2: Moore (2015) | B2: APEX | C2: JP-8 | E2: 273 | F2: 17.6 | G2: 0.93 | H2: 383 | I2: 13.69 | J2: 28 | K2: 4 | L2: NA | M2: 2.49e+15 | N2: 3.82e+16 | O2: 4.07e+16 | P2: 52.74 | Q2: NA | R2: NA | S2: NA | T2: NA | U2: 16.9 | V2: 32.6 | W2: 12.4 | X2: 37.2
A3: Moore (2015) | B3: APEX | C3: JP-8 | E3: 445 | F3: 17.6 | G3: 0.93 | H3: 383 | I3: 13.69 | J3: 32 | K3: 4 | L3: 0.098 | M3: 2.26e+15 | N3: 2.8e+16 | O3: 3.03e+16 | P3: 12.37 | Q3: 0.87 | R3: 0.13 | S3: 129.42829 | T3: 19.324948 | U3: 16.5 | V3: 27.2 | W3: 12.7 | X3: 28.8
A4: Moore (2015) | B4: APEX | C4: JP-8 | E4: 50 | F4: 17.6 | G4: 0.93 | H4: 383 | I4: 13.69 | J4: 34 | K4: 4 | L4: 0.094 | M4: 2.18e+15 | N4: 2.68e+16 | O4: 2.9e+16 | P4: 12.49 | Q4: 0.928 | R4: 0.072 | S4: 82.929467 | T4: 6.4095375 | U4: 15.1 | V4: 29 | W4: 11.8 | X4: 65.8
A5: Moore (2015) | B5: APEX | C5: JP-8 | E5: 266 | F5: 17.6 | G5: 0.93 | H5: 383 | I5: 13.69 | J5: 33 | K5: 4 | L5: 0.098 | M5: 1.79e+15 | N5: 2.26e+16 | O5: 2.44e+16 | P5: 11.33 | Q5: 0.769 | R5: 0.231 | S5: 86.26623 | T5: 25.879593 | U5: 16.4 | V5: 28.2 | W5: 12.7 | X5: 38.5
A6: Moore (2015) | B6: APEX | C6: JP-8 | E6: 674 | F6: 17.6 | G6: 0.93 | H6: 383 | I6: 13.69 | J6: 33 | K6: 4 | L6: 0.096 | M6: 1.88e+15 | N6: 2.2e+16 | O6: 2.39e+16 | P6: 9.77 | Q6: 0.863 | R6: 0.137 | S6: 111.66999 | T6: 17.689407 | U6: 16.4 | V6: 27.4 | W6: 12.5 | X6: 30.4
A7: Moore (2015) | B7: APEX | C7: JP-8 | E7: 262 | F7: 17.6 | G7: 0.93 | H7: 383 | I7: 13.69 | J7: 35 | K7: 4 | L7: 0.1 | M7: 1.73e+15 | N7: 2.73e+16 | O7: 2.91e+16 | P7: NA | Q7: NA | R7: NA | S7: NA | T7: NA | U7: 19.3 | V7: 28.7 | W7: 14.7 | X7: 30.5
A8: Moore (2015) | B8: APEX | C8: JP-8 | E8: 231 | F8: 17.6 | G8: 0.93 | H8: 383 | I8: 13.69 | J8: 22 | K8: 4 | L8: 0.093 | M8: 3.23e+15 | N8: 4.69e+16 | O8: 5.01e+16 | P8: NA | Q8: NA | R8: NA | S8: NA | T8: NA | U8: 16.3 | V8: 25 | W8: 11.2 | X8: 31.2
A9: Moore (2015) | B9: APEX | C9: JP-8 | E9: 395 | F9: 17.6 | G9: 0.93 | H9: 383 | I9: 13.69 | J9: 24 | K9: 4 | L9: 0.092 | M9: 2.99e+15 | N9: 4.64e+16 | O9: 4.94e+16 | P9: 14.05 | Q9: NA | R9: NA | S9: NA | T9: NA | U9: 16.2 | V9: 24.6 | W9: 11.3 | X9: 27
A10: Moore (2015) | B10: APEX | C10: Sulfur | E10: 154 | F10: 17.3 | G10: 1.31 | H10: 1595 | I10: 13.67 | J10: 33 | K10: 4 | L10: 0.096 | M10: 2.54e+15 | N10: 3.54e+16 | O10: 3.79e+16 | P10: NA | Q10: NA | R10: NA | S10: NA | T10: NA | U10: 15.8 | V10: 24.8 | W10: 12 | X10: 31.8
A11: Moore (2015) | B11: APEX | C11: Sulfur | E11: 217 | F11: 17.3 | G11: 1.31 | H11: 1595 | I11: 13.67 | J11: 33 | K11: 4 | L11: 0.096 | M11: 3.75e+15 | N11: 4.48e+16 | O11: 4.85e+16 | P11: NA | Q11: NA | R11: NA | S11: NA | T11: NA | U11: 16.3 | V11: 24 | W11: 12.4 | X11: 23.3
A12: Moore (2015) | B12: APEX | C12: Sulfur | E12: 265 | F12: 17.3 | G12: 1.31 | H12: 1595 | I12: 13.67 | J12: 33 | K12: 4 | L12: 0.096 | M12: 3.91e+15 | N12: 4.63e+16 | O12: 5.02e+16 | P12: 10.88 | Q12: NA | R12: NA | S12: NA | T12: NA | U12: 16.7 | V12: 23.7 | W12: 12.4 | X12: 23.1
A13: Moore (2015) | B13: APEX | C13: Sulfur | E13: 260 | F13: 17.3 | G13: 1.31 | H13: 1595 | I13: 13.67 | J13: 33 | K13: 4 | L13: 0.097 | M13: 3.78e+15 | N13: 5.83e+16 | O13: 6.21e+16 | P13: 8.42 | Q13: 0.685 | R13: 0.315 | S13: 107.30418 | T13: 49.446629 | U13: 16.8 | V13: 22.6 | W13: 12.5 | X13: 24.7
A14: Moore (2015) | B14: APEX | C14: Sulfur | E14: 249 | F14: 17.3 | G14: 1.31 | H14: 1595 | I14: 13.67 | J14: 25 | K14: 4 | L14: 0.097 | M14: 5.07e+15 | N14: 5.59e+16 | O14: 6.09e+16 | P14: -0.96 | Q14: NA | R14: NA | S14: NA | T14: NA | U14: 16.5 | V14: 22.1 | W14: 11.5 | X14: 19.1
A15: Moore (2015) | B15: APEX | C15: Sulfur | E15: 283 | F15: 17.3 | G15: 1.31 | H15: 1595 | I15: 13.67 | J15: 26 | K15: 4 | L15: 0.097 | M15: 4.53e+15 | N15: 5.48e+16 | O15: 5.93e+16 | P15: 11.73 | Q15: 0.771 | R15: 0.229 | S15: 110.26422 | T15: 32.831207 | U15: 16.2 | V15: 22.1 | W15: 11.5 | X15: 19.9
A16: Moore (2015) | B16: APEX | C16: Aromatic | E16: 222 | F16: 21.8 | G16: 1.34 | H16: 530 | I16: 13.7 | J16: 29 | K16: 4 | L16: 0.095 | M16: 2.76e+15 | N16: 3.41e+16 | O16: 3.68e+16 | P16: 11.46 | Q16: 0.824 | R16: 0.176 | S16: 59.20948 | T16: 12.609899 | U16: 14.1 | V16: 22.2 | W16: 11.3 | X16: 26.7
A17: Moore (2015) | B17: APEX | C17: Aromatic | E17: 339 | F17: 21.8 | G17: 1.34 | H17: 530 | I17: 13.7 | J17: 29 | K17: 4 | L17: 0.096 | M17: 1.45e+15 | N17: 3.29e+16 | O17: 3.44e+16 | P17: 9.2 | Q17: 0.787 | R17: 0.213 | S17: 45.17547 | T17: 12.239324 | U17: 13.2 | V17: 20.3 | W17: 10.5 | X17: 26.7
A18: Moore (2015) | B18: APEX | C18: Aromatic | E18: 267 | F18: 21.8 | G18: 1.34 | H18: 530 | I18: 13.7 | J18: 22 | K18: 4 | L18: 0.094 | M18: 4.8e+15 | N18: 5.29e+16 | O18: 5.77e+16 | P18: 21.14 | Q18: 0.962 | R18: 0.038 | S18: 239.16409 | T18: 9.4822273 | U18: 18.1 | V18: 25.6 | W18: 11.9 | X18: 28.5
A19: Moore (2015) | B19: APEX | C19: Aromatic | E19: 270 | F19: 21.8 | G19: 1.34 | H19: 530 | I19: 13.7 | J19: 19 | K19: 4 | L19: 0.096 | M19: 4.48e+15 | N19: 5.43e+16 | O19: 5.88e+16 | P19: 12.11 | Q19: 0.937 | R19: 0.063 | S19: 182.48056 | T19: 12.176999 | U19: 16.9 | V19: 23.4 | W19: 11.5 | X19: 22.6
A20: Moore (2015) | B20: APEX | C20: JP-8 | E20: 165 | F20: 17.6 | G20: 0.93 | H20: 383 | I20: 13.69 | J20: NA | K20: 4 | L20: NA | M20: NA | N20: NA | O20: NA | P20: 11.47 | Q20: NA | R20: NA | S20: NA | T20: NA | U20: 16.6 | V20: 29.3 | W20: NA | X20: NA
A21: Moore (2015) | B21: APEX | C21: JP-8 | E21: 131 | F21: 17.6 | G21: 0.93 | H21: 383 | I21: 13.69 | J21: NA | K21: 4 | L21: NA | M21: NA | N21: NA | O21: NA | P21: 41.9 | Q21: 0.929 | R21: 0.071 | S21: NA | T21: NA | U21: 19.3 | V21: 32 | W21: NA | X21: NA
A22: Moore (2015) | B22: AAFEX-I | C22: JP-8 | E22: 120 | F22: 18.6 | G22: 1.6 | H22: 1148 | I22: 13.6 | J22: 1.3 | K22: 4 | L22: 0.124 | M22: 2.65e+15 | N22: 3.72e+16 | O22: 3.99e+16 | P22: 40.07 | Q22: NA | R22: NA | S22: NA | T22: NA | U22: 21.6 | V22: 31.2 | W22: 12.9 | X22: 34.8
A23: Moore (2015) | B23: AAFEX-I | C23: JP-8 | E23: 140 | F23: 18.6 | G23: 1.6 | H23: 1148 | I23: 13.6 | J23: 1.6 | K23: 4 | L23: 0.152 | M23: 3.57e+15 | N23: 4.12e+16 | O23: 4.48e+16 | P23: 77.57 | Q23: NA | R23: NA | S23: NA | T23: NA | U23: 21.2 | V23: 31.9 | W23: 13.5 | X23: 38.9
A24: Moore (2015) | B24: AAFEX-I | C24: JP-8 | E24: 200 | F24: 18.6 | G24: 1.6 | H24: 1148 | I24: 13.6 | J24: 1.9 | K24: 4 | L24: 0.124 | M24: 2.27e+15 | N24: 3.89e+16 | O24: 4.11e+16 | P24: 23.83 | Q24: NA | R24: NA | S24: NA | T24: NA | U24: 19.3 | V24: 27.9 | W24: 12.6 | X24: 33.3
A25: Moore (2015) | B25: AAFEX-I | C25: JP-8 | E25: 180 | F25: 18.6 | G25: 1.6 | H25: 1148 | I25: 13.6 | J25: 2.1 | K25: 4 | L25: 0.152 | M25: 2.32e+15 | N25: 4.78e+16 | O25: 5.01e+16 | P25: 23.8 | Q25: NA | R25: NA | S25: NA | T25: NA | U25: 19.2 | V25: 27.7 | W25: 12.6 | X25: 34
A26: Moore (2015) | B26: AAFEX-I | C26: JP-8 | E26: 1360 | F26: 18.6 | G26: 1.6 | H26: 1148 | I26: 13.6 | J26: 3.4 | K26: 4 | L26: 0.124 | M26: 2.1e+15 | N26: 3.76e+16 | O26: 3.97e+16 | P26: 20.55 | Q26: NA | R26: NA | S26: NA | T26: NA | U26: 19.1 | V26: 27.1 | W26: 12.1 | X26: 32
A27: Moore (2015) | B27: AAFEX-I | C27: JP-8 | E27: 240 | F27: 18.6 | G27: 1.6 | H27: 1148 | I27: 13.6 | J27: 4.9 | K27: 4 | L27: 0.152 | M27: 6.58e+15 | N27: 1.74e+15 | O27: 8.32e+15 | P27: 85.79 | Q27: NA | R27: NA | S27: NA | T27: NA | U27: 20 | V27: 32.6 | W27: 11.9 | X27: 28.3
A28: Moore (2015) | B28: AAFEX-I | C28: JP-8 | E28: 306 | F28: 18.6 | G28: 1.6 | H28: 1148 | I28: 13.6 | J28: 6.2 | K28: 4 | L28: 0.137 | M28: 2.1e+15 | N28: 4.82e+16 | O28: 5.03e+16 | P28: 19.91 | Q28: NA | R28: NA | S28: NA | T28: NA | U28: 17.7 | V28: 24.3 | W28: 11.7 | X28: 27.3
A29: Moore (2015) | B29: AAFEX-I | C29: JP-8 | E29: 150 | F29: 18.6 | G29: 1.6 | H29: 1148 | I29: 13.6 | J29: 6.4 | K29: 4 | L29: 0.124 | M29: 2.11e+15 | N29: 3.82e+16 | O29: 4.03e+16 | P29: 18.66 | Q29: NA | R29: NA | S29: NA | T29: NA | U29: 18.5 | V29: 25.4 | W29: 11.8 | X29: 26.7
A30: Moore (2015) | B30: AAFEX-I | C30: JP-8 | E30: 113 | F30: 18.6 | G30: 1.6 | H30: 1148 | I30: 13.6 | J30: 7.3 | K30: 4 | L30: 0.138 | M30: 2.44e+15 | N30: 2.42e+16 | O30: 2.66e+16 | P30: 24.8 | Q30: NA | R30: NA | S30: NA | T30: NA | U30: 21.1 | V30: 42.1 | W30: 12.5 | X30: 79.8
A31: Moore (2015) | B31: AAFEX-I | C31: JP-8 | E31: 134 | F31: 18.6 | G31: 1.6 | H31: 1148 | I31: 13.6 | J31: 6.4 | K31: 4 | L31: 0.111 | M31: 2.74e+15 | N31: 3.85e+16 | O31: 4.12e+16 | P31: 21.24 | Q31: NA | R31: NA | S31: NA | T31: NA | U31: 19.9 | V31: 31.2 | W31: 12 | X31: 74.9
A32: Moore (2015) | B32: AAFEX-I | C32: JP-8 | E32: 720 | F32: 18.6 | G32: 1.6 | H32: 1148 | I32: 13.6 | J32: 8.8 | K32: 4 | L32: 0.124 | M32: 3.47e+15 | N32: 3.59e+16 | O32: 3.94e+16 | P32: 45.8 | Q32: NA | R32: NA | S32: NA | T32: NA | U32: 20 | V32: 31.5 | W32: 12.9 | X32: 39.4
A33: Moore (2015) | B33: AAFEX-I | C33: JP-8 | E33: 135 | F33: 18.6 | G33: 1.6 | H33: 1148 | I33: 13.6 | J33: 8.8 | K33: 4 | L33: 0.138 | M33: 2.52e+15 | N33: 7.05e+15 | O33: 9.57e+15 | P33: 31.31 | Q33: NA | R33: NA | S33: NA | T33: NA | U33: 17.1 | V33: 23.5 | W33: 12.1 | X33: 25.4
A34: Moore (2015) | B34: AAFEX-I | C34: JP-8 | E34: 120 | F34: 18.6 | G34: 1.6 | H34: 1148 | I34: 13.6 | J34: 10.2 | K34: 4 | L34: 0.151 | M34: 3.11e+15 | N34: 6.61e+16 | O34: 6.92e+16 | P34: 16.79 | Q34: NA | R34: NA | S34: NA | T34: NA | U34: 16 | V34: 22.9 | W34: 12 | X34: 30.5
A35: Moore (2015) | B35: AAFEX-I | C35: JP-8 | E35: 181 | F35: 18.6 | G35: 1.6 | H35: 1148 | I35: 13.6 | J35: -3.3 | K35: 4 | L35: 0.112 | M35: 3.29e+15 | N35: 4.46e+16 | O35: 4.79e+16 | P35: 33.72 | Q35: 0.996 | R35: 0.004 | S35: 468.57224 | T35: 1.652804 | U35: 21.6 | V35: 30.5 | W35: 12.6 | X35: 34.5
A36: Moore (2015) | B36: AAFEX-I | C36: JP-8 | E36: 118 | F36: 18.6 | G36: 1.6 | H36: 1148 | I36: 13.6 | J36: -2.9 | K36: 4 | L36: 0.14 | M36: 3.19e+15 | N36: 6.09e+16 | O36: 6.41e+16 | P36: 33.67 | Q36: NA | R36: NA | S36: NA | T36: NA | U36: 20.1 | V36: 28.9 | W36: 12.1 | X36: 33.4
A37: Moore (2015) | B37: AAFEX-I | C37: JP-8 | E37: 127 | F37: 18.6 | G37: 1.6 | H37: 1148 | I37: 13.6 | J37: 3.9 | K37: 4 | L37: 0.138 | M37: 7.31e+15 | N37: 4.49e+15 | O37: 1.18e+16 | P37: 41.45 | Q37: NA | R37: NA | S37: NA | T37: NA | U37: 12.8 | V37: 29.2 | W37: 13.7 | X37: 38.7
A38: Moore (2015) | B38: AAFEX-I | C38: JP-8 | E38: 163 | F38: 18.6 | G38: 1.6 | H38: 1148 | I38: 13.6 | J38: 4 | K38: 4 | L38: 0.138 | M38: NA | N38: NA | O38: 5.38e+16 | P38: 25.79 | Q38: 0.99 | R38: 0.01 | S38: 66.06307 | T38: 0.67853032 | U38: 19.1 | V38: 26.9 | W38: 19.8 | X38: 28.7
A39: Moore (2015) | B39: AAFEX-I | C39: JP-8 | E39: 150 | F39: 18.6 | G39: 1.6 | H39: 1148 | I39: 13.6 | J39: 11.4 | K39: 4 | L39: 0.123 | M39: 9.62e+15 | N39: 2.74e+16 | O39: 3.71e+16 | P39: 28.6 | Q39: NA | R39: NA | S39: NA | T39: NA | U39: 19.8 | V39: 29.6 | W39: 20.2 | X39: 31
A40: Moore (2015) | B40: AAFEX-I | C40: FT1 | E40: 189 | F40: 0 | G40: 0 | H40: 19 | I40: 15.5 | J40: 11.6 | K40: 4 | L40: 0.137 | M40: NA | N40: NA | O40: 5.47e+16 | P40: 35.68 | Q40: NA | R40: NA | S40: NA | T40: NA | U40: 18.8 | V40: 28.9 | W40: 20.2 | X40: 34.8
...

Sheet PM Emissions
A1: Source | B1: Campaign | C1: Ground level or cruise | D1: Engine | E1: Probe distance (m) | F1: Thrust setting | G1: Fuel | H1: Reference fuel | I1: Aromatics | J1: Naph | K1: Sulfur | L1: Hydrogen | M1: Temp | N1: TempK | O1: Thrust | P1: FF | Q1: nvPM EIn | R1: vPM EIn | S1: Total PM EIn | T1: mBC | U1: Org_Fract | V1: SO4_Fract | W1: mOrg | X1: mSO4 | Y1: nvPM number geometric diam | Z1: Total EI number geometric diam | AA1: nvPM EIn std dev | AB1: vPM EIn std dev | AC1: Total PM EIn std dev | AD1: Helper key | AE1: relative aromatics | AF1: relative naph | AG1: relative sulfur | AH1: relative Hydrogen | AI1: relative tempC | AJ1: relative TempK | AK1: relative thrust | AL1: relative FF | AM1: relative nvPM EIn | AN1: relative vPM EIn | AO1: relative total PM EIn | AP1: relative mBC | AQ1: relative Org Frac | AR1: relative SO4 Frac | AS1: ΔmOrg | AT1: relative mSO4 | AU1: relative nvPM number geometric diam | AV1: relative total aerosol number geometric diam | AW1: Ref Hydrogen | AX1: Δhydrogen | AY1: FF sea level | AZ1: Hydrogen measurement technique
A2: Markl (2024) | B2: ECLIF3 | C2: Cruise | D2: XWB-84 | E2: 50 | F2: Climb | G2: Ref Jet A | I2: 13.4 | J2: 0.35 | K2: 211 | L2: 14.08 | M2: 213.3 | N2: 213.3 | O2: 57.5 | P2: =2700 -> 2700 | Q2: =9.5*10^14 -> 950000000000000 | Y2: 24.2794 | Z2: 15.1591 | AA2: =(0.3)*10^15 -> 300000000000000 | AD2: =A2 & "|" & B2 & "|" & C2 & "|" & D2 & "|" & E2 &"|" & F2 -> Markl (2024)|ECLIF3|Cruise|XWB-84|50|Climb | AZ2: ASTM D7171
A3: Markl (2024) | B3: ECLIF3 | C3: Cruise | D3: XWB-84 | E3: 50 | F3: Climb | G3: 100% HEFA | H3: Ref Jet A | I3: 0.41 | J3: 0.002 | K3: 7 | L3: 15.11 | M3: 213.8 | N3: 213.8 | O3: 57.5 | P3: =2751.3 -> 2751.3 | Q3: =6.1*10^14 -> 610000000000000 | Y3: 30.0971 | Z3: 14.57 | AA3: =(0.07)*10^15 -> 7e+13 | AD3: =A3 & "|" & B3 & "|" & C3 & "|" & D3 & "|" & E3 &"|" & F3 -> Markl (2024)|ECLIF3|Cruise|XWB-84|50|Climb | AE3: {=I3 / _xlfn.XLOOKUP($AD3 & "|" & $H3, $AD:$AD & "|" & $G:$G, I:I)} -> 0.030597015 | AF3: {=J3 / _xlfn.XLOOKUP($AD3 & "|" & $H3, $AD:$AD & "|" & $G:$G, J:J)} -> 0.0057142857 | AG3: {=K3 / _xlfn.XLOOKUP($AD3 & "|" & $H3, $AD:$AD & "|" & $G:$G, K:K)} -> 0.033175355 | AH3: {=L3 / _xlfn.XLOOKUP($AD3 & "|" & $H3, $AD:$AD & "|" & $G:$G, L:L)} -> 1.0731534 | AI3: {=M3 / _xlfn.XLOOKUP($AD3 & "|" & $H3, $AD:$AD & "|" & $G:$G, M:M)} -> 1.0023441 | AJ3: {=N3 / _xlfn.XLOOKUP($AD3 & "|" & $H3, $AD:$AD & "|" & $G:$G, N:N)} -> 1.0023441 | AK3: {=O3 / _xlfn.XLOOKUP($AD3 & "|" & $H3, $AD:$AD & "|" & $G:$G, O:O)} -> 1 | AL3: {=P3 / _xlfn.XLOOKUP($AD3 & "|" & $H3, $AD:$AD & "|" & $G:$G, P:P)} -> 1.019 | AM3: {=Q3 / _xlfn.XLOOKUP($AD3 & "|" & $H3, $AD:$AD & "|" & $G:$G, Q:Q)} -> 0.64210526 | AU3: =(Y3)/Y2 -> 1.2396147 | AW3: {=_xlfn.XLOOKUP($AD3 & "|" & $H3, $AD:$AD & "|" & $G:$G, L:L)} -> 14.08 | AZ3: ASTM D7171
A4: Voigt (2021) | B4: ECLIF2/ND-MAX | C4: Cruise | D4: V2527-A5 | E4: 24000 | G4: Ref1 Jet A | I4: 18.8 | J4: 1.51 | K4: 1170 | L4: 13.67 | Y4: NA | Z4: 32.2006 | AD4: =A4 & "|" & B4 & "|" & C4 & "|" & D4 & "|" & E4 &"|" & F4 -> Voigt (2021)|ECLIF2/ND-MAX|Cruise|V2527-A5|24000| | AW4: {=_xlfn.XLOOKUP($AD4 & "|" & $H4, $AD:$AD & "|" & $G:$G, L:L)} -> #N/A | AZ4: ASTM D7171
A5: Voigt (2021) | B5: ECLIF2/ND-MAX | C5: Cruise | D5: V2527-A5 | E5: 24000 | F5: Climb | G5: Ref2 Jet A | I5: 17.2 | J5: 1.83 | K5: 1350 | L5: 13.73 | M5: 215 | N5: 215 | O5: =81 -> 81 | P5: 1180 | Q5: =4.9*10^15 -> 4.9e+15 | AA5: =(0.6)*10^15 -> 600000000000000 | AD5: =A5 & "|" & B5 & "|" & C5 & "|" & D5 & "|" & E5 &"|" & F5 -> Voigt (2021)|ECLIF2/ND-MAX|Cruise|V2527-A5|24000|Climb | AW5: {=_xlfn.XLOOKUP($AD5 & "|" & $H5, $AD:$AD & "|" & $G:$G, L:L)} -> #N/A | AZ5: ASTM D7171
A6: Voigt (2021) | B6: ECLIF2/ND-MAX | C6: Cruise | D6: V2527-A5 | E6: 24000 | F6: Climb | G6: Ref3 Jet A | I6: 18.6 | J6: 1.17 | K6: 120 | L6: 13.65 | M6: 215 | N6: 215 | Q6: =3.8*10^15 -> 3.8e+15 | AA6: =(0.9)*10^15 -> 900000000000000 | AD6: =A6 & "|" & B6 & "|" & C6 & "|" & D6 & "|" & E6 &"|" & F6 -> Voigt (2021)|ECLIF2/ND-MAX|Cruise|V2527-A5|24000|Climb | AW6: {=_xlfn.XLOOKUP($AD6 & "|" & $H6, $AD:$AD & "|" & $G:$G, L:L)} -> #N/A | AZ6: ASTM D7171
A7: Voigt (2021) | B7: ECLIF2/ND-MAX | C7: Cruise | D7: V2527-A5 | E7: 24000 | F7: Climb | G7: Ref4 Jet A | I7: 16.5 | J7: 0.13 | K7: 10 | L7: 14.08 | AD7: =A7 & "|" & B7 & "|" & C7 & "|" & D7 & "|" & E7 &"|" & F7 -> Voigt (2021)|ECLIF2/ND-MAX|Cruise|V2527-A5|24000|Climb | AW7: {=_xlfn.XLOOKUP($AD7 & "|" & $H7, $AD:$AD & "|" & $G:$G, L:L)} -> #N/A | AZ7: ASTM D7171
A8: Voigt (2021) | B8: ECLIF2/ND-MAX | C8: Cruise | D8: V2527-A5 | E8: 24000 | F8: Climb | G8: SSF1 (59% Ref1 + 41% FT) | H8: Ref2 Jet A | I8: 11.4 | J8: 0.82 | K8: 570 | L8: 14.36 | M8: 220 | N8: 220 | O8: 81 | P8: 820 | Q8: =2.5*10^15 -> 2.5e+15 | AA8: =(0.2)*10^15 -> 200000000000000 | AD8: =A8 & "|" & B8 & "|" & C8 & "|" & D8 & "|" & E8 &"|" & F8 -> Voigt (2021)|ECLIF2/ND-MAX|Cruise|V2527-A5|24000|Climb | AE8: {=I8 / _xlfn.XLOOKUP($AD8 & "|" & $H8, $AD:$AD & "|" & $G:$G, I:I)} -> 0.6627907 | AF8: {=J8 / _xlfn.XLOOKUP($AD8 & "|" & $H8, $AD:$AD & "|" & $G:$G, J:J)} -> 0.44808743 | AG8: {=K8 / _xlfn.XLOOKUP($AD8 & "|" & $H8, $AD:$AD & "|" & $G:$G, K:K)} -> 0.42222222 | AH8: {=L8 / _xlfn.XLOOKUP($AD8 & "|" & $H8, $AD:$AD & "|" & $G:$G, L:L)} -> 1.0458849 | AI8: {=M8 / _xlfn.XLOOKUP($AD8 & "|" & $H8, $AD:$AD & "|" & $G:$G, M:M)} -> 1.0232558 | AJ8: {=N8 / _xlfn.XLOOKUP($AD8 & "|" & $H8, $AD:$AD & "|" & $G:$G, N:N)} -> 1.0232558 | AK8: {=O8 / _xlfn.XLOOKUP($AD8 & "|" & $H8, $AD:$AD & "|" & $G:$G, O:O)} -> 1 | AL8: {=P8 / _xlfn.XLOOKUP($AD8 & "|" & $H8, $AD:$AD & "|" & $G:$G, P:P)} -> 0.69491525 | AM8: {=Q8 / _xlfn.XLOOKUP($AD8 & "|" & $H8, $AD:$AD & "|" & $G:$G, Q:Q)} -> 0.51020408 | AW8: {=_xlfn.XLOOKUP($AD8 & "|" & $H8, $AD:$AD & "|" & $G:$G, L:L)} -> 13.73 | AZ8: ASTM D7171
A9: Voigt (2021) | B9: ECLIF2/ND-MAX | C9: Cruise | D9: V2527-A5 | E9: 24000 | F9: Climb | G9: SAF1 (51% Ref3 + HEFA 49%) | H9: Ref2 Jet A | I9: 8.4 | J9: 0.61 | K9: 70 | L9: 14.4 | M9: 284 | N9: 284 | O9: 81 | P9: =1132 -> 1132 | Q9: =2.7*10^15 -> 2.7e+15 | AA9: =(0.6)*10^15 -> 600000000000000 | AD9: =A9 & "|" & B9 & "|" & C9 & "|" & D9 & "|" & E9 &"|" & F9 -> Voigt (2021)|ECLIF2/ND-MAX|Cruise|V2527-A5|24000|Climb | AE9: {=I9 / _xlfn.XLOOKUP($AD9 & "|" & $H9, $AD:$AD & "|" & $G:$G, I:I)} -> 0.48837209 | AF9: {=J9 / _xlfn.XLOOKUP($AD9 & "|" & $H9, $AD:$AD & "|" & $G:$G, J:J)} -> 0.33333333 | AG9: {=K9 / _xlfn.XLOOKUP($AD9 & "|" & $H9, $AD:$AD & "|" & $G:$G, K:K)} -> 0.051851852 | AH9: {=L9 / _xlfn.XLOOKUP($AD9 & "|" & $H9, $AD:$AD & "|" & $G:$G, L:L)} -> 1.0487983 | AI9: {=M9 / _xlfn.XLOOKUP($AD9 & "|" & $H9, $AD:$AD & "|" & $G:$G, M:M)} -> 1.3209302 | AJ9: {=N9 / _xlfn.XLOOKUP($AD9 & "|" & $H9, $AD:$AD & "|" & $G:$G, N:N)} -> 1.3209302 | AK9: {=O9 / _xlfn.XLOOKUP($AD9 & "|" & $H9, $AD:$AD & "|" & $G:$G, O:O)} -> 1 | AL9: {=P9 / _xlfn.XLOOKUP($AD9 & "|" & $H9, $AD:$AD & "|" & $G:$G, P:P)} -> 0.95932203 | AM9: {=Q9 / _xlfn.XLOOKUP($AD9 & "|" & $H9, $AD:$AD & "|" & $G:$G, Q:Q)} -> 0.55102041 | AW9: {=_xlfn.XLOOKUP($AD9 & "|" & $H9, $AD:$AD & "|" & $G:$G, L:L)} -> 13.73 | AZ9: ASTM D7171
A10: Voigt (2021) | B10: ECLIF2/ND-MAX | C10: Cruise | D10: V2527-A5 | E10: 24000 | F10: Climb | G10: SAF2 (70% Ref4 + HEFA 30%) | H10: Ref2 Jet A | I10: 9.5 | J10: 0.045 | K10: 10 | L10: 14.51 | M10: 218 | N10: 218 | O10: 81 | P10: =1091 -> 1091 | Q10: =2.3*10^15 -> 2.3e+15 | AA10: =(0.6)*10^15 -> 600000000000000 | AD10: =A10 & "|" & B10 & "|" & C10 & "|" & D10 & "|" & E10 &"|" & F10 -> Voigt (2021)|ECLIF2/ND-MAX|Cruise|V2527-A5|24000|Climb | AE10: {=I10 / _xlfn.XLOOKUP($AD10 & "|" & $H10, $AD:$AD & "|" & $G:$G, I:I)} -> 0.55232558 | AF10: {=J10 / _xlfn.XLOOKUP($AD10 & "|" & $H10, $AD:$AD & "|" & $G:$G, J:J)} -> 0.024590164 | AG10: {=K10 / _xlfn.XLOOKUP($AD10 & "|" & $H10, $AD:$AD & "|" & $G:$G, K:K)} -> 0.0074074074 | AH10: {=L10 / _xlfn.XLOOKUP($AD10 & "|" & $H10, $AD:$AD & "|" & $G:$G, L:L)} -> 1.0568099 | AI10: {=M10 / _xlfn.XLOOKUP($AD10 & "|" & $H10, $AD:$AD & "|" & $G:$G, M:M)} -> 1.0139535 | AJ10: {=N10 / _xlfn.XLOOKUP($AD10 & "|" & $H10, $AD:$AD & "|" & $G:$G, N:N)} -> 1.0139535 | AK10: {=O10 / _xlfn.XLOOKUP($AD10 & "|" & $H10, $AD:$AD & "|" & $G:$G, O:O)} -> 1 | AL10: {=P10 / _xlfn.XLOOKUP($AD10 & "|" & $H10, $AD:$AD & "|" & $G:$G, P:P)} -> 0.92457627 | AM10: {=Q10 / _xlfn.XLOOKUP($AD10 & "|" & $H10, $AD:$AD & "|" & $G:$G, Q:Q)} -> 0.46938776 | AW10: {=_xlfn.XLOOKUP($AD10 & "|" & $H10, $AD:$AD & "|" & $G:$G, L:L)} -> 13.73 | AZ10: ASTM D7171
A11: Lobo (2011) | B11: ARI & AFRL | C11: Ground | D11: CFM56-7B | E11: 1 | F11: Idle (min) | G11: Jet-A1 | I11: 18.5 | L11: 13.8 | M11: =4 + 273.15 -> 277.15 | N11: =4 + 273.15 -> 277.15 | O11: 3 | P11: 700 | AD11: =A11 & "|" & B11 & "|" & C11 & "|" & D11 & "|" & E11 &"|" & F11 -> Lobo (2011)|ARI & AFRL|Ground|CFM56-7B|1|Idle (min) | AW11: {=_xlfn.XLOOKUP($AD11 & "|" & $H11, $AD:$AD & "|" & $G:$G, L:L)} -> #N/A | AZ11: Unknown
A12: Lobo (2011) | B12: ARI & AFRL | C12: Ground | D12: CFM56-7B | E12: 1 | F12: Idle (min) | G12: 50% F-T/50% Jet-A1 | H12: Jet-A1 | I12: 9.25 | L12: 14.52 | M12: 273.15 | N12: 273.15 | O12: 3 | P12: 700 | AD12: =A12 & "|" & B12 & "|" & C12 & "|" & D12 & "|" & E12 &"|" & F12 -> Lobo (2011)|ARI & AFRL|Ground|CFM56-7B|1|Idle (min) | AE12: {=I12 / _xlfn.XLOOKUP($AD12 & "|" & $H12, $AD:$AD & "|" & $G:$G, I:I)} -> 0.5 | AF12: {=J12 / _xlfn.XLOOKUP($AD12 & "|" & $H12, $AD:$AD & "|" & $G:$G, J:J)} -> #DIV/0! | AG12: {=K12 / _xlfn.XLOOKUP($AD12 & "|" & $H12, $AD:$AD & "|" & $G:$G, K:K)} -> #DIV/0! | AH12: {=L12 / _xlfn.XLOOKUP($AD12 & "|" & $H12, $AD:$AD & "|" & $G:$G, L:L)} -> 1.0521739 | AI12: {=M12 / _xlfn.XLOOKUP($AD12 & "|" & $H12, $AD:$AD & "|" & $G:$G, M:M)} -> 0.98556738 | AJ12: {=N12 / _xlfn.XLOOKUP($AD12 & "|" & $H12, $AD:$AD & "|" & $G:$G, N:N)} -> 0.98556738 | AK12: {=O12 / _xlfn.XLOOKUP($AD12 & "|" & $H12, $AD:$AD & "|" & $G:$G, O:O)} -> 1 | AL12: {=P12 / _xlfn.XLOOKUP($AD12 & "|" & $H12, $AD:$AD & "|" & $G:$G, P:P)} -> 1 | AM12: =1-0.85 -> 0.15 | AP12: =1-0.84 -> 0.16 | AW12: {=_xlfn.XLOOKUP($AD12 & "|" & $H12, $AD:$AD & "|" & $G:$G, L:L)} -> 13.8 | AZ12: Unknown
A13: Lobo (2011) | B13: ARI & AFRL | C13: Ground | D13: CFM56-7B | E13: 1 | F13: Idle (min) | G13: 100% F-T | H13: Jet-A1 | I13: 0.2 | L13: 15.32 | M13: 273.15 | N13: 273.15 | O13: 3 | P13: 700 | AD13: =A13 & "|" & B13 & "|" & C13 & "|" & D13 & "|" & E13 &"|" & F13 -> Lobo (2011)|ARI & AFRL|Ground|CFM56-7B|1|Idle (min) | AE13: {=I13 / _xlfn.XLOOKUP($AD13 & "|" & $H13, $AD:$AD & "|" & $G:$G, I:I)} -> 0.010810811 | AF13: {=J13 / _xlfn.XLOOKUP($AD13 & "|" & $H13, $AD:$AD & "|" & $G:$G, J:J)} -> #DIV/0! | AG13: {=K13 / _xlfn.XLOOKUP($AD13 & "|" & $H13, $AD:$AD & "|" & $G:$G, K:K)} -> #DIV/0! | AH13: {=L13 / _xlfn.XLOOKUP($AD13 & "|" & $H13, $AD:$AD & "|" & $G:$G, L:L)} -> 1.1101449 | AI13: {=M13 / _xlfn.XLOOKUP($AD13 & "|" & $H13, $AD:$AD & "|" & $G:$G, M:M)} -> 0.98556738 | AJ13: {=N13 / _xlfn.XLOOKUP($AD13 & "|" & $H13, $AD:$AD & "|" & $G:$G, N:N)} -> 0.98556738 | AK13: {=O13 / _xlfn.XLOOKUP($AD13 & "|" & $H13, $AD:$AD & "|" & $G:$G, O:O)} -> 1 | AL13: {=P13 / _xlfn.XLOOKUP($AD13 & "|" & $H13, $AD:$AD & "|" & $G:$G, P:P)} -> 1 | AM13: =1-0.94 -> 0.06 | AP13: =1-0.9 -> 0.1 | AW13: {=_xlfn.XLOOKUP($AD13 & "|" & $H13, $AD:$AD & "|" & $G:$G, L:L)} -> 13.8 | AZ13: Unknown
A14: Lobo (2011) | B14: ARI & AFRL | C14: Ground | D14: CFM56-7B | E14: 1 | F14: Idle (approach) | G14: Jet-A1 | I14: 18.5 | L14: 13.8 | M14: =4 + 273.15 -> 277.15 | N14: =4 + 273.15 -> 277.15 | O14: 7 | P14: 940 | AD14: =A14 & "|" & B14 & "|" & C14 & "|" & D14 & "|" & E14 &"|" & F14 -> Lobo (2011)|ARI & AFRL|Ground|CFM56-7B|1|Idle (approach) | AW14: {=_xlfn.XLOOKUP($AD14 & "|" & $H14, $AD:$AD & "|" & $G:$G, L:L)} -> #N/A | AZ14: Unknown
A15: Lobo (2011) | B15: ARI & AFRL | C15: Ground | D15: CFM56-7B | E15: 1 | F15: Idle (approach) | G15: 50% F-T/50% Jet-A1 | H15: Jet-A1 | I15: 9.25 | L15: 14.52 | M15: 273.15 | N15: 273.15 | O15: 7 | P15: 940 | AD15: =A15 & "|" & B15 & "|" & C15 & "|" & D15 & "|" & E15 &"|" & F15 -> Lobo (2011)|ARI & AFRL|Ground|CFM56-7B|1|Idle (approach) | AE15: {=I15 / _xlfn.XLOOKUP($AD15 & "|" & $H15, $AD:$AD & "|" & $G:$G, I:I)} -> 0.5 | AF15: {=J15 / _xlfn.XLOOKUP($AD15 & "|" & $H15, $AD:$AD & "|" & $G:$G, J:J)} -> #DIV/0! | AG15: {=K15 / _xlfn.XLOOKUP($AD15 & "|" & $H15, $AD:$AD & "|" & $G:$G, K:K)} -> #DIV/0! | AH15: {=L15 / _xlfn.XLOOKUP($AD15 & "|" & $H15, $AD:$AD & "|" & $G:$G, L:L)} -> 1.0521739 | AI15: {=M15 / _xlfn.XLOOKUP($AD15 & "|" & $H15, $AD:$AD & "|" & $G:$G, M:M)} -> 0.98556738 | AJ15: {=N15 / _xlfn.XLOOKUP($AD15 & "|" & $H15, $AD:$AD & "|" & $G:$G, N:N)} -> 0.98556738 | AK15: {=O15 / _xlfn.XLOOKUP($AD15 & "|" & $H15, $AD:$AD & "|" & $G:$G, O:O)} -> 1 | AL15: {=P15 / _xlfn.XLOOKUP($AD15 & "|" & $H15, $AD:$AD & "|" & $G:$G, P:P)} -> 1 | AM15: =1-0.74 -> 0.26 | AP15: =1-0.65 -> 0.35 | AU15: =0.93 -> 0.93 | AW15: {=_xlfn.XLOOKUP($AD15 & "|" & $H15, $AD:$AD & "|" & $G:$G, L:L)} -> 13.8 | AZ15: Unknown
A16: Lobo (2011) | B16: ARI & AFRL | C16: Ground | D16: CFM56-7B | E16: 1 | F16: Idle (approach) | G16: 100% F-T | H16: Jet-A1 | I16: 0.2 | L16: 15.32 | M16: 273.15 | N16: 273.15 | O16: 7 | P16: 940 | AD16: =A16 & "|" & B16 & "|" & C16 & "|" & D16 & "|" & E16 &"|" & F16 -> Lobo (2011)|ARI & AFRL|Ground|CFM56-7B|1|Idle (approach) | AE16: {=I16 / _xlfn.XLOOKUP($AD16 & "|" & $H16, $AD:$AD & "|" & $G:$G, I:I)} -> 0.010810811 | AF16: {=J16 / _xlfn.XLOOKUP($AD16 & "|" & $H16, $AD:$AD & "|" & $G:$G, J:J)} -> #DIV/0! | AG16: {=K16 / _xlfn.XLOOKUP($AD16 & "|" & $H16, $AD:$AD & "|" & $G:$G, K:K)} -> #DIV/0! | AH16: {=L16 / _xlfn.XLOOKUP($AD16 & "|" & $H16, $AD:$AD & "|" & $G:$G, L:L)} -> 1.1101449 | AI16: {=M16 / _xlfn.XLOOKUP($AD16 & "|" & $H16, $AD:$AD & "|" & $G:$G, M:M)} -> 0.98556738 | AJ16: {=N16 / _xlfn.XLOOKUP($AD16 & "|" & $H16, $AD:$AD & "|" & $G:$G, N:N)} -> 0.98556738 | AK16: {=O16 / _xlfn.XLOOKUP($AD16 & "|" & $H16, $AD:$AD & "|" & $G:$G, O:O)} -> 1 | AL16: {=P16 / _xlfn.XLOOKUP($AD16 & "|" & $H16, $AD:$AD & "|" & $G:$G, P:P)} -> 1 | AM16: =1-0.93 -> 0.07 | AP16: =1-0.67 -> 0.33 | AU16: =0.8 -> 0.8 | AW16: {=_xlfn.XLOOKUP($AD16 & "|" & $H16, $AD:$AD & "|" & $G:$G, L:L)} -> 13.8 | AZ16: Unknown
A17: Lobo (2011) | B17: ARI & AFRL | C17: Ground | D17: CFM56-7B | E17: 1 | F17: Intermediate | G17: Jet-A1 | I17: 18.5 | L17: 13.8 | M17: =4 + 273.15 -> 277.15 | N17: =4 + 273.15 -> 277.15 | O17: 30 | P17: 2800 | AD17: =A17 & "|" & B17 & "|" & C17 & "|" & D17 & "|" & E17 &"|" & F17 -> Lobo (2011)|ARI & AFRL|Ground|CFM56-7B|1|Intermediate | AW17: {=_xlfn.XLOOKUP($AD17 & "|" & $H17, $AD:$AD & "|" & $G:$G, L:L)} -> #N/A | AZ17: Unknown
A18: Lobo (2011) | B18: ARI & AFRL | C18: Ground | D18: CFM56-7B | E18: 1 | F18: Intermediate | G18: 50% F-T/50% Jet-A1 | H18: Jet-A1 | I18: 9.25 | L18: 14.52 | M18: 273.15 | N18: 273.15 | O18: 30 | P18: 2800 | AD18: =A18 & "|" & B18 & "|" & C18 & "|" & D18 & "|" & E18 &"|" & F18 -> Lobo (2011)|ARI & AFRL|Ground|CFM56-7B|1|Intermediate | AE18: {=I18 / _xlfn.XLOOKUP($AD18 & "|" & $H18, $AD:$AD & "|" & $G:$G, I:I)} -> 0.5 | AF18: {=J18 / _xlfn.XLOOKUP($AD18 & "|" & $H18, $AD:$AD & "|" & $G:$G, J:J)} -> #DIV/0! | AG18: {=K18 / _xlfn.XLOOKUP($AD18 & "|" & $H18, $AD:$AD & "|" & $G:$G, K:K)} -> #DIV/0! | AH18: {=L18 / _xlfn.XLOOKUP($AD18 & "|" & $H18, $AD:$AD & "|" & $G:$G, L:L)} -> 1.0521739 | AI18: {=M18 / _xlfn.XLOOKUP($AD18 & "|" & $H18, $AD:$AD & "|" & $G:$G, M:M)} -> 0.98556738 | AJ18: {=N18 / _xlfn.XLOOKUP($AD18 & "|" & $H18, $AD:$AD & "|" & $G:$G, N:N)} -> 0.98556738 | AK18: {=O18 / _xlfn.XLOOKUP($AD18 & "|" & $H18, $AD:$AD & "|" & $G:$G, O:O)} -> 1 | AL18: {=P18 / _xlfn.XLOOKUP($AD18 & "|" & $H18, $AD:$AD & "|" & $G:$G, P:P)} -> 1 | AM18: =1-0.48 -> 0.52 | AP18: =1-0.63 -> 0.37 | AU18: =0.94 -> 0.94 | AW18: {=_xlfn.XLOOKUP($AD18 & "|" & $H18, $AD:$AD & "|" & $G:$G, L:L)} -> 13.8 | AZ18: Unknown
A19: Lobo (2011) | B19: ARI & AFRL | C19: Ground | D19: CFM56-7B | E19: 1 | F19: Intermediate | G19: 100% F-T | H19: Jet-A1 | I19: 0.2 | L19: 15.32 | M19: 273.15 | N19: 273.15 | O19: 30 | P19: 2800 | AD19: =A19 & "|" & B19 & "|" & C19 & "|" & D19 & "|" & E19 &"|" & F19 -> Lobo (2011)|ARI & AFRL|Ground|CFM56-7B|1|Intermediate | AE19: {=I19 / _xlfn.XLOOKUP($AD19 & "|" & $H19, $AD:$AD & "|" & $G:$G, I:I)} -> 0.010810811 | AF19: {=J19 / _xlfn.XLOOKUP($AD19 & "|" & $H19, $AD:$AD & "|" & $G:$G, J:J)} -> #DIV/0! | AG19: {=K19 / _xlfn.XLOOKUP($AD19 & "|" & $H19, $AD:$AD & "|" & $G:$G, K:K)} -> #DIV/0! | AH19: {=L19 / _xlfn.XLOOKUP($AD19 & "|" & $H19, $AD:$AD & "|" & $G:$G, L:L)} -> 1.1101449 | AI19: {=M19 / _xlfn.XLOOKUP($AD19 & "|" & $H19, $AD:$AD & "|" & $G:$G, M:M)} -> 0.98556738 | AJ19: {=N19 / _xlfn.XLOOKUP($AD19 & "|" & $H19, $AD:$AD & "|" & $G:$G, N:N)} -> 0.98556738 | AK19: {=O19 / _xlfn.XLOOKUP($AD19 & "|" & $H19, $AD:$AD & "|" & $G:$G, O:O)} -> 1 | AL19: {=P19 / _xlfn.XLOOKUP($AD19 & "|" & $H19, $AD:$AD & "|" & $G:$G, P:P)} -> 1 | AM19: =1-0.77 -> 0.23 | AP19: =1-0.89 -> 0.11 | AU19: =0.84 -> 0.84 | AW19: {=_xlfn.XLOOKUP($AD19 & "|" & $H19, $AD:$AD & "|" & $G:$G, L:L)} -> 13.8 | AZ19: Unknown
A20: Lobo (2011) | B20: ARI & AFRL | C20: Ground | D20: CFM56-7B | E20: 1 | F20: Mid-power | G20: Jet-A1 | I20: 18.5 | L20: 13.8 | M20: =4 + 273.15 -> 277.15 | N20: =4 + 273.15 -> 277.15 | O20: 45 | P20: 4200 | AD20: =A20 & "|" & B20 & "|" & C20 & "|" & D20 & "|" & E20 &"|" & F20 -> Lobo (2011)|ARI & AFRL|Ground|CFM56-7B|1|Mid-power | AW20: {=_xlfn.XLOOKUP($AD20 & "|" & $H20, $AD:$AD & "|" & $G:$G, L:L)} -> #N/A | AZ20: Unknown
A21: Lobo (2011) | B21: ARI & AFRL | C21: Ground | D21: CFM56-7B | E21: 1 | F21: Mid-power | G21: 50% F-T/50% Jet-A1 | H21: Jet-A1 | I21: 9.25 | L21: 14.52 | M21: 273.15 | N21: 273.15 | O21: 45 | P21: 4200 | AD21: =A21 & "|" & B21 & "|" & C21 & "|" & D21 & "|" & E21 &"|" & F21 -> Lobo (2011)|ARI & AFRL|Ground|CFM56-7B|1|Mid-power | AE21: {=I21 / _xlfn.XLOOKUP($AD21 & "|" & $H21, $AD:$AD & "|" & $G:$G, I:I)} -> 0.5 | AF21: {=J21 / _xlfn.XLOOKUP($AD21 & "|" & $H21, $AD:$AD & "|" & $G:$G, J:J)} -> #DIV/0! | AG21: {=K21 / _xlfn.XLOOKUP($AD21 & "|" & $H21, $AD:$AD & "|" & $G:$G, K:K)} -> #DIV/0! | AH21: {=L21 / _xlfn.XLOOKUP($AD21 & "|" & $H21, $AD:$AD & "|" & $G:$G, L:L)} -> 1.0521739 | AI21: {=M21 / _xlfn.XLOOKUP($AD21 & "|" & $H21, $AD:$AD & "|" & $G:$G, M:M)} -> 0.98556738 | AJ21: {=N21 / _xlfn.XLOOKUP($AD21 & "|" & $H21, $AD:$AD & "|" & $G:$G, N:N)} -> 0.98556738 | AK21: {=O21 / _xlfn.XLOOKUP($AD21 & "|" & $H21, $AD:$AD & "|" & $G:$G, O:O)} -> 1 | AL21: {=P21 / _xlfn.XLOOKUP($AD21 & "|" & $H21, $AD:$AD & "|" & $G:$G, P:P)} -> 1 | AM21: =1-0.44 -> 0.56 | AP21: =1-0.68 -> 0.32 | AW21: {=_xlfn.XLOOKUP($AD21 & "|" & $H21, $AD:$AD & "|" & $G:$G, L:L)} -> 13.8 | AZ21: Unknown
A22: Lobo (2011) | B22: ARI & AFRL | C22: Ground | D22: CFM56-7B | E22: 1 | F22: Mid-power | G22: 100% F-T | H22: Jet-A1 | I22: 0.2 | L22: 15.32 | M22: 273.15 | N22: 273.15 | O22: 45 | P22: 4200 | R22: =L21-L23 -> 0.72 | AD22: =A22 & "|" & B22 & "|" & C22 & "|" & D22 & "|" & E22 &"|" & F22 -> Lobo (2011)|ARI & AFRL|Ground|CFM56-7B|1|Mid-power | AE22: {=I22 / _xlfn.XLOOKUP($AD22 & "|" & $H22, $AD:$AD & "|" & $G:$G, I:I)} -> 0.010810811 | AF22: {=J22 / _xlfn.XLOOKUP($AD22 & "|" & $H22, $AD:$AD & "|" & $G:$G, J:J)} -> #DIV/0! | AG22: {=K22 / _xlfn.XLOOKUP($AD22 & "|" & $H22, $AD:$AD & "|" & $G:$G, K:K)} -> #DIV/0! | AH22: {=L22 / _xlfn.XLOOKUP($AD22 & "|" & $H22, $AD:$AD & "|" & $G:$G, L:L)} -> 1.1101449 | AI22: {=M22 / _xlfn.XLOOKUP($AD22 & "|" & $H22, $AD:$AD & "|" & $G:$G, M:M)} -> 0.98556738 | AJ22: {=N22 / _xlfn.XLOOKUP($AD22 & "|" & $H22, $AD:$AD & "|" & $G:$G, N:N)} -> 0.98556738 | AK22: {=O22 / _xlfn.XLOOKUP($AD22 & "|" & $H22, $AD:$AD & "|" & $G:$G, O:O)} -> 1 | AL22: {=P22 / _xlfn.XLOOKUP($AD22 & "|" & $H22, $AD:$AD & "|" & $G:$G, P:P)} -> 1 | AM22: =1-0.67 -> 0.33 | AP22: =1-0.89 -> 0.11 | AW22: {=_xlfn.XLOOKUP($AD22 & "|" & $H22, $AD:$AD & "|" & $G:$G, L:L)} -> 13.8 | AZ22: Unknown
A23: Lobo (2011) | B23: ARI & AFRL | C23: Ground | D23: CFM56-7B | E23: 1 | F23: Mid-high power | G23: Jet-A1 | I23: 18.5 | L23: 13.8 | M23: =4 + 273.15 -> 277.15 | N23: =4 + 273.15 -> 277.15 | O23: 65 | P23: 6350 | AD23: =A23 & "|" & B23 & "|" & C23 & "|" & D23 & "|" & E23 &"|" & F23 -> Lobo (2011)|ARI & AFRL|Ground|CFM56-7B|1|Mid-high power | AZ23: Unknown
A24: Lobo (2011) | B24: ARI & AFRL | C24: Ground | D24: CFM56-7B | E24: 1 | F24: Mid-high power | G24: 50% F-T/50% Jet-A1 | H24: Jet-A1 | I24: 9.25 | L24: 14.52 | M24: 273.15 | N24: 273.15 | O24: 65 | P24: 6350 | AD24: =A24 & "|" & B24 & "|" & C24 & "|" & D24 & "|" & E24 &"|" & F24 -> Lobo (2011)|ARI & AFRL|Ground|CFM56-7B|1|Mid-high power | AE24: {=I24 / _xlfn.XLOOKUP($AD24 & "|" & $H24, $AD:$AD & "|" & $G:$G, I:I)} -> 0.5 | AF24: {=J24 / _xlfn.XLOOKUP($AD24 & "|" & $H24, $AD:$AD & "|" & $G:$G, J:J)} -> #DIV/0! | AG24: {=K24 / _xlfn.XLOOKUP($AD24 & "|" & $H24, $AD:$AD & "|" & $G:$G, K:K)} -> #DIV/0! | AH24: {=L24 / _xlfn.XLOOKUP($AD24 & "|" & $H24, $AD:$AD & "|" & $G:$G, L:L)} -> 1.0521739 | AI24: {=M24 / _xlfn.XLOOKUP($AD24 & "|" & $H24, $AD:$AD & "|" & $G:$G, M:M)} -> 0.98556738 | AJ24: {=N24 / _xlfn.XLOOKUP($AD24 & "|" & $H24, $AD:$AD & "|" & $G:$G, N:N)} -> 0.98556738 | AK24: {=O24 / _xlfn.XLOOKUP($AD24 & "|" & $H24, $AD:$AD & "|" & $G:$G, O:O)} -> 1 | AL24: {=P24 / _xlfn.XLOOKUP($AD24 & "|" & $H24, $AD:$AD & "|" & $G:$G, P:P)} -> 1 | AM24: =1-0.3 -> 0.7 | AP24: =1-0.56 -> 0.44 | AW24: {=_xlfn.XLOOKUP($AD24 & "|" & $H24, $AD:$AD & "|" & $G:$G, L:L)} -> 13.8 | AZ24: Unknown
A25: Lobo (2011) | B25: ARI & AFRL | C25: Ground | D25: CFM56-7B | E25: 1 | F25: Mid-high power | G25: 100% F-T | H25: Jet-A1 | I25: 0.2 | L25: 15.32 | M25: 273.15 | N25: 273.15 | O25: 65 | P25: 6350 | AD25: =A25 & "|" & B25 & "|" & C25 & "|" & D25 & "|" & E25 &"|" & F25 -> Lobo (2011)|ARI & AFRL|Ground|CFM56-7B|1|Mid-high power | AE25: {=I25 / _xlfn.XLOOKUP($AD25 & "|" & $H25, $AD:$AD & "|" & $G:$G, I:I)} -> 0.010810811 | AF25: {=J25 / _xlfn.XLOOKUP($AD25 & "|" & $H25, $AD:$AD & "|" & $G:$G, J:J)} -> #DIV/0! | AG25: {=K25 / _xlfn.XLOOKUP($AD25 & "|" & $H25, $AD:$AD & "|" & $G:$G, K:K)} -> #DIV/0! | AH25: {=L25 / _xlfn.XLOOKUP($AD25 & "|" & $H25, $AD:$AD & "|" & $G:$G, L:L)} -> 1.1101449 | AI25: {=M25 / _xlfn.XLOOKUP($AD25 & "|" & $H25, $AD:$AD & "|" & $G:$G, M:M)} -> 0.98556738 | AJ25: {=N25 / _xlfn.XLOOKUP($AD25 & "|" & $H25, $AD:$AD & "|" & $G:$G, N:N)} -> 0.98556738 | AK25: {=O25 / _xlfn.XLOOKUP($AD25 & "|" & $H25, $AD:$AD & "|" & $G:$G, O:O)} -> 1 | AL25: {=P25 / _xlfn.XLOOKUP($AD25 & "|" & $H25, $AD:$AD & "|" & $G:$G, P:P)} -> 1 | AM25: =1-0.49 -> 0.51 | AP25: =1-0.79 -> 0.21 | AW25: {=_xlfn.XLOOKUP($AD25 & "|" & $H25, $AD:$AD & "|" & $G:$G, L:L)} -> 13.8 | AZ25: Unknown
A26: Lobo (2011) | B26: ARI & AFRL | C26: Ground | D26: CFM56-7B | E26: 1 | F26: Climb | G26: Jet-A1 | I26: 18.5 | L26: 13.8 | M26: =4 + 273.15 -> 277.15 | N26: =4 + 273.15 -> 277.15 | O26: 85 | P26: 8260 | AD26: =A26 & "|" & B26 & "|" & C26 & "|" & D26 & "|" & E26 &"|" & F26 -> Lobo (2011)|ARI & AFRL|Ground|CFM56-7B|1|Climb | AW26: {=_xlfn.XLOOKUP($AD26 & "|" & $H26, $AD:$AD & "|" & $G:$G, L:L)} -> #N/A | AZ26: Unknown
A27: Lobo (2011) | B27: ARI & AFRL | C27: Ground | D27: CFM56-7B | E27: 1 | F27: Climb | G27: 50% F-T/50% Jet-A1 | H27: Jet-A1 | I27: 9.25 | L27: 14.52 | M27: 273.15 | N27: 273.15 | O27: 85 | P27: 8260 | AD27: =A27 & "|" & B27 & "|" & C27 & "|" & D27 & "|" & E27 &"|" & F27 -> Lobo (2011)|ARI & AFRL|Ground|CFM56-7B|1|Climb | AE27: {=I27 / _xlfn.XLOOKUP($AD27 & "|" & $H27, $AD:$AD & "|" & $G:$G, I:I)} -> 0.5 | AF27: {=J27 / _xlfn.XLOOKUP($AD27 & "|" & $H27, $AD:$AD & "|" & $G:$G, J:J)} -> #DIV/0! | AG27: {=K27 / _xlfn.XLOOKUP($AD27 & "|" & $H27, $AD:$AD & "|" & $G:$G, K:K)} -> #DIV/0! | AH27: {=L27 / _xlfn.XLOOKUP($AD27 & "|" & $H27, $AD:$AD & "|" & $G:$G, L:L)} -> 1.0521739 | AI27: {=M27 / _xlfn.XLOOKUP($AD27 & "|" & $H27, $AD:$AD & "|" & $G:$G, M:M)} -> 0.98556738 | AJ27: {=N27 / _xlfn.XLOOKUP($AD27 & "|" & $H27, $AD:$AD & "|" & $G:$G, N:N)} -> 0.98556738 | AK27: {=O27 / _xlfn.XLOOKUP($AD27 & "|" & $H27, $AD:$AD & "|" & $G:$G, O:O)} -> 1 | AL27: {=P27 / _xlfn.XLOOKUP($AD27 & "|" & $H27, $AD:$AD & "|" & $G:$G, P:P)} -> 1 | AM27: =1-0.29 -> 0.71 | AP27: =1-0.36 -> 0.64 | AU27: =1.01 -> 1.01 | AW27: {=_xlfn.XLOOKUP($AD27 & "|" & $H27, $AD:$AD & "|" & $G:$G, L:L)} -> 13.8 | AZ27: Unknown
A28: Lobo (2011) | B28: ARI & AFRL | C28: Ground | D28: CFM56-7B | E28: 1 | F28: Climb | G28: 100% F-T | H28: Jet-A1 | I28: 0.2 | L28: 15.32 | M28: 273.15 | N28: 273.15 | O28: 85 | P28: 8260 | AD28: =A28 & "|" & B28 & "|" & C28 & "|" & D28 & "|" & E28 &"|" & F28 -> Lobo (2011)|ARI & AFRL|Ground|CFM56-7B|1|Climb | AE28: {=I28 / _xlfn.XLOOKUP($AD28 & "|" & $H28, $AD:$AD & "|" & $G:$G, I:I)} -> 0.010810811 | AF28: {=J28 / _xlfn.XLOOKUP($AD28 & "|" & $H28, $AD:$AD & "|" & $G:$G, J:J)} -> #DIV/0! | AG28: {=K28 / _xlfn.XLOOKUP($AD28 & "|" & $H28, $AD:$AD & "|" & $G:$G, K:K)} -> #DIV/0! | AH28: {=L28 / _xlfn.XLOOKUP($AD28 & "|" & $H28, $AD:$AD & "|" & $G:$G, L:L)} -> 1.1101449 | AI28: {=M28 / _xlfn.XLOOKUP($AD28 & "|" & $H28, $AD:$AD & "|" & $G:$G, M:M)} -> 0.98556738 | AJ28: {=N28 / _xlfn.XLOOKUP($AD28 & "|" & $H28, $AD:$AD & "|" & $G:$G, N:N)} -> 0.98556738 | AK28: {=O28 / _xlfn.XLOOKUP($AD28 & "|" & $H28, $AD:$AD & "|" & $G:$G, O:O)} -> 1 | AL28: {=P28 / _xlfn.XLOOKUP($AD28 & "|" & $H28, $AD:$AD & "|" & $G:$G, P:P)} -> 1 | AM28: =1-0.42 -> 0.58 | AP28: =1-0.6 -> 0.4 | AU28: =0.95 -> 0.95 | AW28: {=_xlfn.XLOOKUP($AD28 & "|" & $H28, $AD:$AD & "|" & $G:$G, L:L)} -> 13.8 | AZ28: Unknown
A29: Lobo (2011) | B29: ARI & AFRL | C29: Ground | D29: CFM56-7B | E29: 1 | F29: Take-off | G29: Jet-A1 | I29: 18.5 | L29: 13.8 | M29: =4 + 273.15 -> 277.15 | N29: =4 + 273.15 -> 277.15 | O29: 100 | P29: 10520 | AD29: =A29 & "|" & B29 & "|" & C29 & "|" & D29 & "|" & E29 &"|" & F29 -> Lobo (2011)|ARI & AFRL|Ground|CFM56-7B|1|Take-off | AW29: {=_xlfn.XLOOKUP($AD29 & "|" & $H29, $AD:$AD & "|" & $G:$G, L:L)} -> #N/A | AZ29: Unknown
A30: Lobo (2011) | B30: ARI & AFRL | C30: Ground | D30: CFM56-7B | E30: 1 | F30: Take-off | G30: 50% F-T/50% Jet-A1 | H30: Jet-A1 | I30: 9.25 | L30: 14.52 | M30: 273.15 | N30: 273.15 | O30: 100 | P30: 10520 | AD30: =A30 & "|" & B30 & "|" & C30 & "|" & D30 & "|" & E30 &"|" & F30 -> Lobo (2011)|ARI & AFRL|Ground|CFM56-7B|1|Take-off | AE30: {=I30 / _xlfn.XLOOKUP($AD30 & "|" & $H30, $AD:$AD & "|" & $G:$G, I:I)} -> 0.5 | AF30: {=J30 / _xlfn.XLOOKUP($AD30 & "|" & $H30, $AD:$AD & "|" & $G:$G, J:J)} -> #DIV/0! | AG30: {=K30 / _xlfn.XLOOKUP($AD30 & "|" & $H30, $AD:$AD & "|" & $G:$G, K:K)} -> #DIV/0! | AH30: {=L30 / _xlfn.XLOOKUP($AD30 & "|" & $H30, $AD:$AD & "|" & $G:$G, L:L)} -> 1.0521739 | AI30: {=M30 / _xlfn.XLOOKUP($AD30 & "|" & $H30, $AD:$AD & "|" & $G:$G, M:M)} -> 0.98556738 | AJ30: {=N30 / _xlfn.XLOOKUP($AD30 & "|" & $H30, $AD:$AD & "|" & $G:$G, N:N)} -> 0.98556738 | AK30: {=O30 / _xlfn.XLOOKUP($AD30 & "|" & $H30, $AD:$AD & "|" & $G:$G, O:O)} -> 1 | AL30: {=P30 / _xlfn.XLOOKUP($AD30 & "|" & $H30, $AD:$AD & "|" & $G:$G, P:P)} -> 1 | AM30: =1-0.22 -> 0.78 | AP30: =1-0.39 -> 0.61 | AU30: =0.92 -> 0.92 | AW30: {=_xlfn.XLOOKUP($AD30 & "|" & $H30, $AD:$AD & "|" & $G:$G, L:L)} -> 13.8 | AZ30: Unknown
A31: Lobo (2011) | B31: ARI & AFRL | C31: Ground | D31: CFM56-7B | E31: 1 | F31: Take-off | G31: 100% F-T | H31: Jet-A1 | I31: 0.2 | L31: 15.32 | M31: 273.15 | N31: 273.15 | O31: 100 | P31: 10520 | AD31: =A31 & "|" & B31 & "|" & C31 & "|" & D31 & "|" & E31 &"|" & F31 -> Lobo (2011)|ARI & AFRL|Ground|CFM56-7B|1|Take-off | AE31: {=I31 / _xlfn.XLOOKUP($AD31 & "|" & $H31, $AD:$AD & "|" & $G:$G, I:I)} -> 0.010810811 | AF31: {=J31 / _xlfn.XLOOKUP($AD31 & "|" & $H31, $AD:$AD & "|" & $G:$G, J:J)} -> #DIV/0! | AG31: {=K31 / _xlfn.XLOOKUP($AD31 & "|" & $H31, $AD:$AD & "|" & $G:$G, K:K)} -> #DIV/0! | AH31: {=L31 / _xlfn.XLOOKUP($AD31 & "|" & $H31, $AD:$AD & "|" & $G:$G, L:L)} -> 1.1101449 | AI31: {=M31 / _xlfn.XLOOKUP($AD31 & "|" & $H31, $AD:$AD & "|" & $G:$G, M:M)} -> 0.98556738 | AJ31: {=N31 / _xlfn.XLOOKUP($AD31 & "|" & $H31, $AD:$AD & "|" & $G:$G, N:N)} -> 0.98556738 | AK31: {=O31 / _xlfn.XLOOKUP($AD31 & "|" & $H31, $AD:$AD & "|" & $G:$G, O:O)} -> 1 | AL31: {=P31 / _xlfn.XLOOKUP($AD31 & "|" & $H31, $AD:$AD & "|" & $G:$G, P:P)} -> 1 | AM31: =1-0.38 -> 0.62 | AP31: =1-0.64 -> 0.36 | AU31: =0.93 -> 0.93 | AW31: {=_xlfn.XLOOKUP($AD31 & "|" & $H31, $AD:$AD & "|" & $G:$G, L:L)} -> 13.8 | AZ31: Unknown
A32: Timko (2010) | B32: Timko (2010) | C32: Ground | D32: PW308 | E32: 1 | F32: Idle (approach) | G32: JP-8 | I32: 19 | J32: =1.4 -> 1.4 | K32: 1230 | L32: 14 | M32: =20.95+273.15 -> 294.1 | N32: =20.95+273.15 -> 294.1 | O32: 7 | AD32: =A32 & "|" & B32 & "|" & C32 & "|" & D32 & "|" & E32 &"|" & F32 -> Timko (2010)|Timko (2010)|Ground|PW308|1|Idle (approach) | AU32: =0.88 -> 0.88 | AW32: {=_xlfn.XLOOKUP($AD32 & "|" & $H32, $AD:$AD & "|" & $G:$G, L:L)} -> #N/A | AZ32: ASTM D3343
A33: Timko (2010) | B33: Timko (2010) | C33: Ground | D33: PW308 | E33: 1 | F33: Idle (approach) | G33: 50% 50% blend | H33: JP-8 | I33: 9.5 | J33: 0.7 | K33: 650 | L33: 14.8 | M33: =20.95+273.15 -> 294.1 | N33: =20.95+273.15 -> 294.1 | O33: 7 | AD33: =A33 & "|" & B33 & "|" & C33 & "|" & D33 & "|" & E33 &"|" & F33 -> Timko (2010)|Timko (2010)|Ground|PW308|1|Idle (approach) | AE33: {=I33 / _xlfn.XLOOKUP($AD33 & "|" & $H33, $AD:$AD & "|" & $G:$G, I:I)} -> 0.5 | AF33: {=J33 / _xlfn.XLOOKUP($AD33 & "|" & $H33, $AD:$AD & "|" & $G:$G, J:J)} -> 0.5 | AG33: {=K33 / _xlfn.XLOOKUP($AD33 & "|" & $H33, $AD:$AD & "|" & $G:$G, K:K)} -> 0.52845528 | AH33: {=L33 / _xlfn.XLOOKUP($AD33 & "|" & $H33, $AD:$AD & "|" & $G:$G, L:L)} -> 1.0571429 | AI33: {=M33 / _xlfn.XLOOKUP($AD33 & "|" & $H33, $AD:$AD & "|" & $G:$G, M:M)} -> 1 | AJ33: {=N33 / _xlfn.XLOOKUP($AD33 & "|" & $H33, $AD:$AD & "|" & $G:$G, N:N)} -> 1 | AK33: {=O33 / _xlfn.XLOOKUP($AD33 & "|" & $H33, $AD:$AD & "|" & $G:$G, O:O)} -> 1 | AL33: {=P33 / _xlfn.XLOOKUP($AD33 & "|" & $H33, $AD:$AD & "|" & $G:$G, P:P)} -> #DIV/0! | AM33: =0.59 -> 0.59 | AP33: =0.78 -> 0.78 | AW33: {=_xlfn.XLOOKUP($AD33 & "|" & $H33, $AD:$AD & "|" & $G:$G, L:L)} -> 14 | AZ33: ASTM D3343
A34: Timko (2010) | B34: Timko (2010) | C34: Ground | D34: PW308 | E34: 1 | F34: Idle (approach) | G34: 100% F-T | H34: JP-8 | I34: 0.2 | J34: 0 | K34: =AVERAGE(L34:L34) -> 15.6 | L34: 15.6 | M34: =20.95+273.15 -> 294.1 | N34: =20.95+273.15 -> 294.1 | O34: 7 | AD34: =A34 & "|" & B34 & "|" & C34 & "|" & D34 & "|" & E34 &"|" & F34 -> Timko (2010)|Timko (2010)|Ground|PW308|1|Idle (approach) | AE34: {=I34 / _xlfn.XLOOKUP($AD34 & "|" & $H34, $AD:$AD & "|" & $G:$G, I:I)} -> 0.010526316 | AF34: {=J34 / _xlfn.XLOOKUP($AD34 & "|" & $H34, $AD:$AD & "|" & $G:$G, J:J)} -> 0 | AG34: {=K34 / _xlfn.XLOOKUP($AD34 & "|" & $H34, $AD:$AD & "|" & $G:$G, K:K)} -> 0.012682927 | AH34: {=L34 / _xlfn.XLOOKUP($AD34 & "|" & $H34, $AD:$AD & "|" & $G:$G, L:L)} -> 1.1142857 | AI34: {=M34 / _xlfn.XLOOKUP($AD34 & "|" & $H34, $AD:$AD & "|" & $G:$G, M:M)} -> 1 | AJ34: {=N34 / _xlfn.XLOOKUP($AD34 & "|" & $H34, $AD:$AD & "|" & $G:$G, N:N)} -> 1 | AK34: {=O34 / _xlfn.XLOOKUP($AD34 & "|" & $H34, $AD:$AD & "|" & $G:$G, O:O)} -> 1 | AL34: {=P34 / _xlfn.XLOOKUP($AD34 & "|" & $H34, $AD:$AD & "|" & $G:$G, P:P)} -> #DIV/0! | AM34: =0.09 -> 0.09 | AP34: =0.02 -> 0.02 | AW34: {=_xlfn.XLOOKUP($AD34 & "|" & $H34, $AD:$AD & "|" & $G:$G, L:L)} -> 14 | AZ34: ASTM D3343
A35: Timko (2010) | B35: Timko (2010) | C35: Ground | D35: PW308 | E35: 1 | F35: Intermediate | G35: JP-8 | I35: 19 | J35: =1.4 -> 1.4 | K35: 1230 | L35: 14 | M35: =20.95+273.15 -> 294.1 | N35: =20.95+273.15 -> 294.1 | O35: 30 | AD35: =A35 & "|" & B35 & "|" & C35 & "|" & D35 & "|" & E35 &"|" & F35 -> Timko (2010)|Timko (2010)|Ground|PW308|1|Intermediate | AW35: {=_xlfn.XLOOKUP($AD35 & "|" & $H35, $AD:$AD & "|" & $G:$G, L:L)} -> #N/A | AZ35: ASTM D3343
A36: Timko (2010) | B36: Timko (2010) | C36: Ground | D36: PW308 | E36: 1 | F36: Intermediate | G36: 50% 50% blend | H36: JP-8 | I36: 9.5 | J36: 0.7 | K36: 650 | L36: 14.8 | M36: =20.95+273.15 -> 294.1 | N36: =20.95+273.15 -> 294.1 | O36: 30 | AD36: =A36 & "|" & B36 & "|" & C36 & "|" & D36 & "|" & E36 &"|" & F36 -> Timko (2010)|Timko (2010)|Ground|PW308|1|Intermediate | AE36: {=I36 / _xlfn.XLOOKUP($AD36 & "|" & $H36, $AD:$AD & "|" & $G:$G, I:I)} -> 0.5 | AF36: {=J36 / _xlfn.XLOOKUP($AD36 & "|" & $H36, $AD:$AD & "|" & $G:$G, J:J)} -> 0.5 | AG36: {=K36 / _xlfn.XLOOKUP($AD36 & "|" & $H36, $AD:$AD & "|" & $G:$G, K:K)} -> 0.52845528 | AH36: {=L36 / _xlfn.XLOOKUP($AD36 & "|" & $H36, $AD:$AD & "|" & $G:$G, L:L)} -> 1.0571429 | AI36: {=M36 / _xlfn.XLOOKUP($AD36 & "|" & $H36, $AD:$AD & "|" & $G:$G, M:M)} -> 1 | AJ36: {=N36 / _xlfn.XLOOKUP($AD36 & "|" & $H36, $AD:$AD & "|" & $G:$G, N:N)} -> 1 | AK36: {=O36 / _xlfn.XLOOKUP($AD36 & "|" & $H36, $AD:$AD & "|" & $G:$G, O:O)} -> 1 | AL36: {=P36 / _xlfn.XLOOKUP($AD36 & "|" & $H36, $AD:$AD & "|" & $G:$G, P:P)} -> #DIV/0! | AM36: =0.57 -> 0.57 | AP36: =0.51 -> 0.51 | AW36: {=_xlfn.XLOOKUP($AD36 & "|" & $H36, $AD:$AD & "|" & $G:$G, L:L)} -> 14 | AZ36: ASTM D3343
A37: Timko (2010) | B37: Timko (2010) | C37: Ground | D37: PW308 | E37: 1 | F37: Intermediate | G37: 100% F-T | H37: JP-8 | I37: 0.2 | J37: 0 | K37: =AVERAGE(L37:L37) -> 15.6 | L37: 15.6 | M37: =20.95+273.15 -> 294.1 | N37: =20.95+273.15 -> 294.1 | O37: 30 | AD37: =A37 & "|" & B37 & "|" & C37 & "|" & D37 & "|" & E37 &"|" & F37 -> Timko (2010)|Timko (2010)|Ground|PW308|1|Intermediate | AE37: {=I37 / _xlfn.XLOOKUP($AD37 & "|" & $H37, $AD:$AD & "|" & $G:$G, I:I)} -> 0.010526316 | AF37: {=J37 / _xlfn.XLOOKUP($AD37 & "|" & $H37, $AD:$AD & "|" & $G:$G, J:J)} -> 0 | AG37: {=K37 / _xlfn.XLOOKUP($AD37 & "|" & $H37, $AD:$AD & "|" & $G:$G, K:K)} -> 0.012682927 | AH37: {=L37 / _xlfn.XLOOKUP($AD37 & "|" & $H37, $AD:$AD & "|" & $G:$G, L:L)} -> 1.1142857 | AI37: {=M37 / _xlfn.XLOOKUP($AD37 & "|" & $H37, $AD:$AD & "|" & $G:$G, M:M)} -> 1 | AJ37: {=N37 / _xlfn.XLOOKUP($AD37 & "|" & $H37, $AD:$AD & "|" & $G:$G, N:N)} -> 1 | AK37: {=O37 / _xlfn.XLOOKUP($AD37 & "|" & $H37, $AD:$AD & "|" & $G:$G, O:O)} -> 1 | AL37: {=P37 / _xlfn.XLOOKUP($AD37 & "|" & $H37, $AD:$AD & "|" & $G:$G, P:P)} -> #DIV/0! | AM37: =0.23 -> 0.23 | AP37: =0.11 -> 0.11 | AW37: {=_xlfn.XLOOKUP($AD37 & "|" & $H37, $AD:$AD & "|" & $G:$G, L:L)} -> 14 | AZ37: ASTM D3343
A38: Timko (2010) | B38: Timko (2010) | C38: Ground | D38: PW308 | E38: 1 | F38: Mid-high power | G38: JP-8 | I38: 19 | J38: =1.4 -> 1.4 | K38: 1230 | L38: 14 | M38: =20.95+273.15 -> 294.1 | N38: =20.95+273.15 -> 294.1 | O38: 65 | AD38: =A38 & "|" & B38 & "|" & C38 & "|" & D38 & "|" & E38 &"|" & F38 -> Timko (2010)|Timko (2010)|Ground|PW308|1|Mid-high power | AW38: {=_xlfn.XLOOKUP($AD38 & "|" & $H38, $AD:$AD & "|" & $G:$G, L:L)} -> #N/A | AZ38: ASTM D3343
A39: Timko (2010) | B39: Timko (2010) | C39: Ground | D39: PW308 | E39: 1 | F39: Mid-high power | G39: 50% 50% blend | H39: JP-8 | I39: 9.5 | J39: 0.7 | K39: 650 | L39: 14.8 | M39: =20.95+273.15 -> 294.1 | N39: =20.95+273.15 -> 294.1 | O39: 65 | AD39: =A39 & "|" & B39 & "|" & C39 & "|" & D39 & "|" & E39 &"|" & F39 -> Timko (2010)|Timko (2010)|Ground|PW308|1|Mid-high power | AE39: {=I39 / _xlfn.XLOOKUP($AD39 & "|" & $H39, $AD:$AD & "|" & $G:$G, I:I)} -> 0.5 | AF39: {=J39 / _xlfn.XLOOKUP($AD39 & "|" & $H39, $AD:$AD & "|" & $G:$G, J:J)} -> 0.5 | AG39: {=K39 / _xlfn.XLOOKUP($AD39 & "|" & $H39, $AD:$AD & "|" & $G:$G, K:K)} -> 0.52845528 | AH39: {=L39 / _xlfn.XLOOKUP($AD39 & "|" & $H39, $AD:$AD & "|" & $G:$G, L:L)} -> 1.0571429 | AI39: {=M39 / _xlfn.XLOOKUP($AD39 & "|" & $H39, $AD:$AD & "|" & $G:$G, M:M)} -> 1 | AJ39: {=N39 / _xlfn.XLOOKUP($AD39 & "|" & $H39, $AD:$AD & "|" & $G:$G, N:N)} -> 1 | AK39: {=O39 / _xlfn.XLOOKUP($AD39 & "|" & $H39, $AD:$AD & "|" & $G:$G, O:O)} -> 1 | AL39: {=P39 / _xlfn.XLOOKUP($AD39 & "|" & $H39, $AD:$AD & "|" & $G:$G, P:P)} -> #DIV/0! | AM39: =0.8 -> 0.8 | AP39: =0.9 -> 0.9 | AW39: {=_xlfn.XLOOKUP($AD39 & "|" & $H39, $AD:$AD & "|" & $G:$G, L:L)} -> 14 | AZ39: ASTM D3343
A40: Timko (2010) | B40: Timko (2010) | C40: Ground | D40: PW308 | E40: 1 | F40: Mid-high power | G40: 100% F-T | H40: JP-8 | I40: 0.2 | J40: 0 | K40: =AVERAGE(L40:L40) -> 15.6 | L40: 15.6 | M40: =20.95+273.15 -> 294.1 | N40: =20.95+273.15 -> 294.1 | O40: 65 | AD40: =A40 & "|" & B40 & "|" & C40 & "|" & D40 & "|" & E40 &"|" & F40 -> Timko (2010)|Timko (2010)|Ground|PW308|1|Mid-high power | AE40: {=I40 / _xlfn.XLOOKUP($AD40 & "|" & $H40, $AD:$AD & "|" & $G:$G, I:I)} -> 0.010526316 | AF40: {=J40 / _xlfn.XLOOKUP($AD40 & "|" & $H40, $AD:$AD & "|" & $G:$G, J:J)} -> 0 | AG40: {=K40 / _xlfn.XLOOKUP($AD40 & "|" & $H40, $AD:$AD & "|" & $G:$G, K:K)} -> 0.012682927 | AH40: {=L40 / _xlfn.XLOOKUP($AD40 & "|" & $H40, $AD:$AD & "|" & $G:$G, L:L)} -> 1.1142857 | AI40: {=M40 / _xlfn.XLOOKUP($AD40 & "|" & $H40, $AD:$AD & "|" & $G:$G, M:M)} -> 1 | AJ40: {=N40 / _xlfn.XLOOKUP($AD40 & "|" & $H40, $AD:$AD & "|" & $G:$G, N:N)} -> 1 | AK40: {=O40 / _xlfn.XLOOKUP($AD40 & "|" & $H40, $AD:$AD & "|" & $G:$G, O:O)} -> 1 | AL40: {=P40 / _xlfn.XLOOKUP($AD40 & "|" & $H40, $AD:$AD & "|" & $G:$G, P:P)} -> #DIV/0! | AM40: =0.53 -> 0.53 | AP40: =0.42 -> 0.42 | AW40: {=_xlfn.XLOOKUP($AD40 & "|" & $H40, $AD:$AD & "|" & $G:$G, L:L)} -> 14 | AZ40: ASTM D3343
...

Sheet Sheet1
A4: Eg no 3 Idle (min) | B4: FT | C4: JP-8 | D4: 1.4 | E4: 0 | F4: 4 | G4: 15 | H4: 285.95 | I4: 285.95 | J4: 4 | K4: 457.2 | L4: #DIV/0!
A5: Eg no 3 Idle (approach) | B5: FT | C5: JP-8 | D5: 1.4 | E5: 0 | F5: 4 | G5: 15 | H5: 286.48333 | I5: 286.48333 | J5: 7 | K5: 561.096 | L5: 32400000000000 | O5: =L5/L11 -> 0.10646221
A6: Eg no 3 Intermediate | B6: FT | C6: JP-8 | D6: 1.4 | E6: 0 | F6: 4 | G6: 15 | H6: 286.75 | I6: 286.75 | J6: 30 | K6: 1231.2 | L6: 22100000000000 | O6: =L6/L12 -> 0.34504294
A7: Eg no 3 Mid power | B7: FT | C7: JP-8 | D7: 1.4 | E7: 0 | F7: 4 | G7: 15 | H7: 286.2 | I7: 286.2 | J7: 65 | K7: 2167.2 | L7: 98800000000000 | O7: =L7/L13 -> 0.77795276
A8: Eg no 3 Climb | B8: FT | C8: JP-8 | D8: 1.4 | E8: 0 | F8: 4 | G8: 15 | H8: 287.15 | I8: 287.15 | J8: 85 | K8: 3042 | L8: 240000000000000 | O8: =L8/L14 -> 0.9486166
A9: Eg no 3 Take-off | B9: FT | C9: JP-8 | D9: 1.4 | E9: 0 | F9: 4 | G9: 15 | H9: 286.45 | I9: 286.45 | J9: 100 | K9: 3218.4 | L9: 314000000000000 | O9: =L9/L15 -> 0.94578313
A10: Eg no 3 Idle (min) | B10: FTS | C10: JP-8 | D10: 2.1 | E10: 0 | F10: 1083 | G10: 15 | H10: 286.45 | I10: 286.45 | J10: 4 | K10: 457.2 | L10: #DIV/0!
A11: Eg no 3 Idle (approach) | B11: FTS | C11: JP-8 | D11: 2.1 | E11: 0 | F11: 1083 | G11: 15 | H11: 287.01667 | I11: 287.01667 | J11: 7 | K11: 561.096 | L11: 3.0433333e+14
A12: Eg no 3 Intermediate | B12: FTS | C12: JP-8 | D12: 2.1 | E12: 0 | F12: 1083 | G12: 15 | H12: 287.05 | I12: 287.05 | J12: 30 | K12: 1231.2 | L12: 64050000000000
A13: Eg no 3 Mid power | B13: FTS | C13: JP-8 | D13: 2.1 | E13: 0 | F13: 1083 | G13: 15 | H13: 287.3 | I13: 287.3 | J13: 65 | K13: 2167.2 | L13: 127000000000000
A14: Eg no 3 Climb | B14: FTS | C14: JP-8 | D14: 2.1 | E14: 0 | F14: 1083 | G14: 15 | H14: 288.15 | I14: 288.15 | J14: 85 | K14: 3042 | L14: 253000000000000
A15: Eg no 3 Take-off | B15: FTS | C15: JP-8 | D15: 2.1 | E15: 0 | F15: 1083 | G15: 15 | H15: 287.05 | I15: 287.05 | J15: 100 | K15: 3218.4 | L15: 332000000000000

Sheet NASA data 30 to 100
A1: ID | B1: Mission | C1: Engine | D1: Fuel | E1: Aromatics | F1: Naph | G1: Sulfur | H1: Hydrogen | I1: TempC | J1: Thrust | K1: FF | L1: HotEIn | M1: VolEIn | N1: ColdEIn | O1: mBC | P1: Org_Fract | Q1: SO4_Fract | R1: mOrg | S1: mSO4 | X1: Engine2 | Y1: Engine3 | Z1: N1 | AA1: N2 | AB1: EGT | AD1: ColdGMD | AE1: ColdVMD | AF1: HotGMD | AG1: HotVMD | AI1: nPoints | AK1: ColdV | AL1: HotV | AM1: VolV
A2: 1 | B2: APEX | C2: 3 | D2: JP-8 | E2: 17.6 | F2: 0.93 | G2: 383 | H2: 13.69 | I2: 21 | J2: 30 | K2: 0.34156214 | L2: 203000000000000 | M2: 8.11e+15 | N2: 8.32e+15 | O2: 2.233 | P2: NA | Q2: NA | R2: NA | S2: NA | X2: 0 | Y2: 1 | Z2: 54.8 | AA2: 83 | AB2: 786 | AD2: 16.205195 | AE2: 37.435572 | AF2: 17.008135 | AG2: 47.75287 | AI2: 158 | AK2: 59 | AL2: 18 | AM2: 41.1
A3: 2 | B3: APEX | C3: 3 | D3: JP-8 | E3: 17.6 | F3: 0.93 | G3: 383 | H3: 13.69 | I3: 22 | J3: 30 | K3: 0.34156214 | L3: 156000000000000 | M3: 1.2e+16 | N3: 1.21e+16 | O3: 4.925 | P3: NA | Q3: NA | R3: NA | S3: NA | X3: 0 | Y3: 1 | Z3: 53.5 | AA3: 83 | AB3: 779 | AD3: 15.16255 | AE3: 24.211165 | AF3: 17.51781 | AG3: 47.42213 | AI3: 191 | AK3: 58.2 | AL3: 13.4 | AM3: 44.8
A4: 3 | B4: APEX | C4: 3 | D4: JP-8 | E4: 17.6 | F4: 0.93 | G4: 383 | H4: 13.69 | I4: 25 | J4: 30 | K4: 0.34156214 | L4: 271000000000000 | M4: 1.16e+16 | N4: 1.19e+16 | O4: 4.632 | P4: NA | Q4: NA | R4: NA | S4: NA | X4: 0 | Y4: 1 | Z4: 52.5 | AA4: 85 | AB4: 781 | AD4: 16.751233 | AE4: 25.48232 | AF4: 12.523088 | AG4: 56.265082 | AI4: 277 | AK4: 93.4 | AL4: 22.5 | AM4: 70.9
A5: 4 | B5: APEX | C5: 3 | D5: JP-8 | E5: 17.6 | F5: 0.93 | G5: 383 | H5: 13.69 | I5: 27 | J5: 30 | K5: 0.34156214 | L5: 225000000000000 | M5: 1.22e+16 | N5: 1.24e+16 | O5: 3.333 | P5: NA | Q5: NA | R5: NA | S5: NA | X5: 0 | Y5: 1 | Z5: 53.5 | AA5: 84 | AB5: 771 | AD5: 16.220578 | AE5: 23.820617 | AF5: 12.56352 | AG5: 56.89679 | AI5: 332 | AK5: 70.5 | AL5: 21.2 | AM5: 49.4
A6: 5 | B6: APEX | C6: NA | D6: NA | E6: NA | F6: NA | G6: NA | H6: NA | I6: NA | J6: 30 | K6: 0.34156214 | L6: NA | M6: NA | N6: NA | O6: NA | P6: NA | Q6: NA | R6: NA | S6: NA | X6: NA | Y6: NA | Z6: NA | AA6: NA | AB6: NA | AD6: NA | AE6: NA | AF6: NA | AG6: NA | AI6: NA | AK6: NA | AL6: NA | AM6: NA
A7: 6 | B7: APEX | C7: 3 | D7: JP-8 | E7: 17.6 | F7: 0.93 | G7: 383 | H7: 13.69 | I7: 33 | J7: 30 | K7: 0.34156214 | L7: 285000000000000 | M7: 1.52e+16 | N7: 1.55e+16 | O7: 4.185 | P7: NA | Q7: NA | R7: NA | S7: NA | X7: 0 | Y7: 1 | Z7: 52 | AA7: 70 | AB7: 804 | AD7: 12.185417 | AE7: 23.201647 | AF7: 13.37111 | AG7: 56.779737 | AI7: 327 | AK7: 32.9 | AL7: 19.1 | AM7: 13.8
A8: 7 | B8: APEX | C8: 3 | D8: JP-8 | E8: 17.6 | F8: 0.93 | G8: 383 | H8: 13.69 | I8: 24 | J8: 30 | K8: 0.34156214 | L8: 112000000000000 | M8: 2.58e+16 | N8: 2.59e+16 | O8: 7.896 | P8: 0.767 | Q8: 0.233 | R8: 21.059777 | S8: 6.4099936 | X8: 0 | Y8: 1 | Z8: 53 | AA8: 85 | AB8: 792 | AD8: 12.002846 | AE8: 19.144358 | AF8: 15.17721 | AG8: 50.698227 | AI8: 280 | AK8: 35.8 | AL8: 12.9 | AM8: 22.9
A9: 8 | B9: APEX | C9: 3 | D9: JP-8 | E9: 17.6 | F9: 0.93 | G9: 383 | H9: 13.69 | I9: 34 | J9: 30 | K9: 0.34156214 | L9: 168000000000000 | M9: 1.23e+16 | N9: 1.24e+16 | O9: 5.739 | P9: 0.481 | Q9: 0.519 | R9: 12.456539 | S9: 13.427221 | X9: 0 | Y9: 1 | Z9: 54 | AA9: 85 | AB9: 805 | AD9: 12.696178 | AE9: 23.133878 | AF9: 12.11744 | AG9: 51.418053 | AI9: 225 | AK9: 37.7 | AL9: 16.1 | AM9: 21.6
A10: 9 | B10: APEX | C10: 3 | D10: Sulfur | E10: 17.3 | F10: 1.31 | G10: 1595 | H10: 13.67 | I10: 33 | J10: 30 | K10: 0.34156214 | L10: 184000000000000 | M10: 5.49e+16 | N10: 5.51e+16 | O10: 5.12 | P10: NA | Q10: NA | R10: NA | S10: NA | X10: 0 | Y10: 1 | Z10: 52.5 | AA10: 85 | AB10: 784 | AD10: 15.543236 | AE10: 20.587301 | AF10: 11.289617 | AG10: 44.919876 | AI10: 287 | AK10: 133.7 | AL10: 12.6 | AM10: 121.1
A11: 10 | B11: APEX | C11: 3 | D11: Sulfur | E11: 17.3 | F11: 1.31 | G11: 1595 | H11: 13.67 | I11: 26 | J11: 30 | K11: 0.34156214 | L11: 105000000000000 | M11: 6.54e+16 | N11: 6.55e+16 | O11: 6.271 | P11: 0.586 | Q11: 0.414 | R11: 112.4067 | S11: 79.452463 | X11: 0 | Y11: 1 | Z11: 52.8 | AA11: 84 | AB11: 774 | AD11: 15.585523 | AE11: 20.277694 | AF11: 12.732518 | AG11: 45.947152 | AI11: 243 | AK11: 172.4 | AL11: 12.6 | AM11: 159.9
A12: 11 | B12: APEX | C12: NA | D12: NA | E12: NA | F12: NA | G12: NA | H12: NA | I12: NA | J12: 30 | K12: 0.34156214 | L12: NA | M12: NA | N12: NA | O12: NA | P12: NA | Q12: NA | R12: NA | S12: NA | X12: NA | Y12: NA | Z12: NA | AA12: NA | AB12: NA | AD12: 14.663411 | AE12: 24.970177 | AF12: NA | AG12: NA | AI12: NA | AK12: NA | AL12: NA | AM12: NA
A13: 12 | B13: APEX | C13: 3 | D13: Aromatic | E13: 21.8 | F13: 1.34 | G13: 530 | H13: 13.7 | I13: 30 | J13: 30 | K13: 0.34156214 | L13: 83800000000000 | M13: 2.97e+16 | N13: 2.98e+16 | O13: 5.12 | P13: 0.519 | Q13: 0.481 | R13: 21.207088 | S13: 19.652157 | X13: 0 | Y13: 1 | Z13: 53.5 | AA13: 85 | AB13: 780 | AD13: 11.93553 | AE13: 17.24499 | AF13: 17.361536 | AG13: 54.593308 | AI13: 230 | AK13: 47.3 | AL13: 13.2 | AM13: 34
A14: 13 | B14: APEX | C14: 3 | D14: Aromatic | E14: 21.8 | F14: 1.34 | G14: 530 | H14: 13.7 | I14: 21 | J14: 30 | K14: 0.34156214 | L14: 125000000000000 | M14: 3.93e+16 | N14: 3.94e+16 | O14: 4.328 | P14: 0.674 | Q14: 0.326 | R14: 36.234059 | S14: 17.531853 | X14: 0 | Y14: 1 | Z14: 53 | AA14: 83 | AB14: 776 | AD14: 12.746729 | AE14: 17.563996 | AF14: 19.248055 | AG14: 46.032952 | AI14: 217 | AK14: 54.9 | AL14: 10.1 | AM14: 44.8
A15: 14 | B15: APEX | C15: 3 | D15: Sulfur | E15: 17.3 | F15: 1.31 | G15: 1595 | H15: 13.67 | I15: 24 | J15: 30 | K15: 0.34156214 | L15: 227000000000000 | M15: 3.84e+16 | N15: 3.87e+16 | O15: 31.729 | P15: 0.637 | Q15: 0.363 | R15: 89.646387 | S15: 51.142377 | X15: 0 | Y15: 1 | Z15: 52 | AA15: 85 | AB15: 807 | AD15: 14.45236 | AE15: 31.603603 | AF15: 20.45368 | AG15: 58.117223 | AI15: 216 | AK15: 177.4 | AL15: 60.1 | AM15: 117.3
A16: 15 | B16: APEX | C16: 3 | D16: Sulfur | E16: 17.3 | F16: 1.31 | G16: 1595 | H16: 13.67 | I16: 24 | J16: 30 | K16: 0.34156214 | L16: 91400000000000 | M16: 5.81e+16 | N16: 5.82e+16 | O16: 4.301 | P16: 0.613 | Q16: 0.387 | R16: 90.989846 | S16: 57.386534 | X16: 0 | Y16: 1 | Z16: 53 | AA16: 83 | AB16: 819 | AD16: 14.43933 | AE16: 22.868701 | AF16: 14.704304 | AG16: 58.579778 | AI16: 259 | AK16: 136.2 | AL16: 12.6 | AM16: 123.6
A17: 16 | B17: AAFEX-I | C17: 3 | D17: JP-8 | E17: 18.6 | F17: 1.6 | G17: 1148 | H17: 13.6 | I17: 5.6 | J17: 30 | K17: 0.34156214 | L17: 360000000000000 | M17: 2.65e+16 | N17: 2.7e+16 | O17: 8.962 | P17: NA | Q17: NA | R17: NA | S17: NA | X17: 0 | Y17: 1 | Z17: 53 | AA17: 71 | AB17: 763 | AD17: 12.7571 | AE17: 19.855 | AF17: 13.153 | AG17: 49.4759 | AI17: 140 | AK17: 68.4 | AL17: 8 | AM17: 60.4
A18: 17 | B18: AAFEX-I | C18: 2 | D18: JP-8 | E18: 18.6 | F18: 1.6 | G18: 1148 | H18: 13.6 | I18: 5.7 | J18: 30 | K18: 0.34156214 | L18: 500000000000000 | M18: 2.54e+16 | N18: 2.6e+16 | O18: 13.029 | P18: NA | Q18: NA | R18: NA | S18: NA | X18: 1 | Y18: 0 | Z18: NA | AA18: NA | AB18: NA | AD18: 13.7169 | AE18: 22.2152 | AF18: 15.5949 | AG18: 54.0442 | AI18: 140 | AK18: 80.7 | AL18: 10.8 | AM18: 69.9
A19: 18 | B19: AAFEX-I | C19: 3 | D19: JP-8 | E19: 18.6 | F19: 1.6 | G19: 1148 | H19: 13.6 | I19: 5.8 | J19: 30 | K19: 0.34156214 | L19: 550000000000000 | M19: 4.4e+16 | N19: 4.5e+16 | O19: 11.631 | P19: NA | Q19: NA | R19: NA | S19: NA | X19: 0 | Y19: 1 | Z19: 83 | AA19: 81 | AB19: 766 | AD19: 15.3705 | AE19: 28.3007 | AF19: 15.0392 | AG19: 165.186 | AI19: 45 | AK19: 104.4 | AL19: 45.8 | AM19: 58.6
A20: 19 | B20: AAFEX-I | C20: 2 | D20: JP-8 | E20: 18.6 | F20: 1.6 | G20: 1148 | H20: 13.6 | I20: 4.8 | J20: 30 | K20: 0.34156214 | L20: 620000000000000 | M20: 2.97e+16 | N20: 3e+16 | O20: 22.116 | P20: NA | Q20: NA | R20: NA | S20: NA | X20: 1 | Y20: 0 | Z20: NA | AA20: NA | AB20: NA | AD20: 15.7994 | AE20: 32.4053 | AF20: 16.3575 | AG20: 122.118 | AI20: 64 | AK20: 92.3 | AL20: 39.7 | AM20: 52.6
A21: 20 | B21: AAFEX-I | C21: 2 | D21: JP-8 | E21: 18.6 | F21: 1.6 | G21: 1148 | H21: 13.6 | I21: 9.2 | J21: 30 | K21: 0.34156214 | L21: 750000000000000 | M21: 7.4e+15 | N21: 8.1e+15 | O21: 27.267 | P21: NA | Q21: NA | R21: NA | S21: NA | X21: 1 | Y21: 0 | Z21: NA | AA21: NA | AB21: NA | AD21: 14.4507 | AE21: 27.4446 | AF21: 16.4515 | AG21: 57.1291 | AI21: 159 | AK21: 105.8 | AL21: 22.6 | AM21: 83.1
A22: 21 | B22: AAFEX-I | C22: 3 | D22: JP-8 | E22: 18.6 | F22: 1.6 | G22: 1148 | H22: 13.6 | I22: 9.2 | J22: 30 | K22: 0.34156214 | L22: 470000000000000 | M22: 3.25e+16 | N22: 3.3e+16 | O22: 12.352 | P22: NA | Q22: NA | R22: NA | S22: NA | X22: 0 | Y22: 1 | Z22: 53 | AA22: 81 | AB22: 769 | AD22: 12.7026 | AE22: 19.8366 | AF22: 14.1073 | AG22: 52.2658 | AI22: 210 | AK22: 75.5 | AL22: 13.2 | AM22: 62.3
A23: 22 | B23: AAFEX-I | C23: 3 | D23: JP-8 | E23: 18.6 | F23: 1.6 | G23: 1148 | H23: 13.6 | I23: 10 | J23: 30 | K23: 0.34156214 | L23: 410000000000000 | M23: 3.15e+16 | N23: 3.2e+16 | O23: 10.889 | P23: NA | Q23: NA | R23: NA | S23: NA | X23: 0 | Y23: 1 | Z23: 53 | AA23: 81 | AB23: 746 | AD23: 13.1735 | AE23: 20.8428 | AF23: 15.6302 | AG23: 50.5555 | AI23: 110 | AK23: 75.4 | AL23: 11 | AM23: 64.5
A24: 23 | B24: AAFEX-I | C24: 3 | D24: JP-8 | E24: 18.6 | F24: 1.6 | G24: 1148 | H24: 13.6 | I24: -4.1 | J24: 30 | K24: 0.34156214 | L24: 570000000000000 | M24: 3.94e+16 | N24: 4e+16 | O24: 15.952 | P24: NA | Q24: NA | R24: NA | S24: NA | X24: 0 | Y24: 1 | Z24: 54 | AA24: 81 | AB24: 745 | AD24: 13.2823 | AE24: 22.1903 | AF24: 17.0766 | AG24: 57.1167 | AI24: 83 | AK24: 97.1 | AL24: 18.5 | AM24: 78.6
